Workbook
Name Slicer_State: #N/A
Name Slicer_State1: #N/A
Name Slicer_State2: #N/A
Name Slicer_State3: #N/A

Sheet Names
A1: Project
A2: Name1 | B2: Bleona Krasniqi Section 7
A3: Name2
A4: Name3
A5: Name4
A6: Group Number

Sheet Raw_Data_CodesPredictions
A1: Model 1 | C1: =IFERROR(VLOOKUP(C$10,'Models training data'!$AG$22:$AH$37,2,FALSE),0) -> 110221.95 | D1: =IFERROR(VLOOKUP(D$10,'Models training data'!$AG$22:$AH$37,2,FALSE),0) -> 0 | E1: =IFERROR(VLOOKUP(E$10,'Models training data'!$AG$22:$AH$37,2,FALSE),0) -> 0 | F1: =IFERROR(VLOOKUP(F$10,'Models training data'!$AG$22:$AH$37,2,FALSE),0) -> 0 | G1: =IFERROR(VLOOKUP(G$10,'Models training data'!$AG$22:$AH$37,2,FALSE),0) -> 0 | H1: =IFERROR(VLOOKUP(H$10,'Models training data'!$AG$22:$AH$37,2,FALSE),0) -> 0 | I1: =IFERROR(VLOOKUP(I$10,'Models training data'!$AG$22:$AH$37,2,FALSE),0) -> 0 | J1: =IFERROR(VLOOKUP(J$10,'Models training data'!$AG$22:$AH$37,2,FALSE),0) -> 0 | ... AQ1: =IFERROR(VLOOKUP(AQ$10,'Models training data'!$AG$22:$AH$37,2,FALSE),0) -> 0
A2: Model 2 | C2: =IFERROR(VLOOKUP(C$10,'Models training data'!$AW$23:$AX$41,2,FALSE),0) -> 101870.91 | D2: =IFERROR(VLOOKUP(D$10,'Models training data'!$AW$23:$AX$41,2,FALSE),0) -> 0 | E2: =IFERROR(VLOOKUP(E$10,'Models training data'!$AW$23:$AX$41,2,FALSE),0) -> 0 | F2: =IFERROR(VLOOKUP(F$10,'Models training data'!$AW$23:$AX$41,2,FALSE),0) -> 0 | G2: =IFERROR(VLOOKUP(G$10,'Models training data'!$AW$23:$AX$41,2,FALSE),0) -> 0 | H2: =IFERROR(VLOOKUP(H$10,'Models training data'!$AW$23:$AX$41,2,FALSE),0) -> 0 | I2: =IFERROR(VLOOKUP(I$10,'Models training data'!$AW$23:$AX$41,2,FALSE),0) -> 0 | J2: =IFERROR(VLOOKUP(J$10,'Models training data'!$AW$23:$AX$41,2,FALSE),0) -> 0 | ... AQ2: =IFERROR(VLOOKUP(AQ$10,'Models training data'!$AW$23:$AX$41,2,FALSE),0) -> 0
A3: Model 3 | C3: =IFERROR(VLOOKUP(C$10,'Models training data'!$BN$23:$BO$41,2,FALSE),0) -> 11.507982 | D3: =IFERROR(VLOOKUP(D$10,'Models training data'!$BN$23:$BO$41,2,FALSE),0) -> 0 | E3: =IFERROR(VLOOKUP(E$10,'Models training data'!$BN$23:$BO$41,2,FALSE),0) -> 0 | F3: =IFERROR(VLOOKUP(F$10,'Models training data'!$BN$23:$BO$41,2,FALSE),0) -> 0 | G3: =IFERROR(VLOOKUP(G$10,'Models training data'!$BN$23:$BO$41,2,FALSE),0) -> 0 | H3: =IFERROR(VLOOKUP(H$10,'Models training data'!$BN$23:$BO$41,2,FALSE),0) -> 0 | I3: =IFERROR(VLOOKUP(I$10,'Models training data'!$BN$23:$BO$41,2,FALSE),0) -> 0 | J3: =IFERROR(VLOOKUP(J$10,'Models training data'!$BN$23:$BO$41,2,FALSE),0) -> 0 | ... AQ3: =IFERROR(VLOOKUP(AQ$10,'Models training data'!$BN$23:$BO$41,2,FALSE),0) -> 0
A4: Model 4 | C4: =IFERROR(VLOOKUP(C$10,'Models training data'!$CD$23:$CE$39,2,FALSE),0) -> 99191.043 | D4: =IFERROR(VLOOKUP(D$10,'Models training data'!$CD$23:$CE$39,2,FALSE),0) -> 0 | E4: =IFERROR(VLOOKUP(E$10,'Models training data'!$CD$23:$CE$39,2,FALSE),0) -> 0 | F4: =IFERROR(VLOOKUP(F$10,'Models training data'!$CD$23:$CE$39,2,FALSE),0) -> 0 | G4: =IFERROR(VLOOKUP(G$10,'Models training data'!$CD$23:$CE$39,2,FALSE),0) -> 0 | H4: =IFERROR(VLOOKUP(H$10,'Models training data'!$CD$23:$CE$39,2,FALSE),0) -> 0 | I4: =IFERROR(VLOOKUP(I$10,'Models training data'!$CD$23:$CE$39,2,FALSE),0) -> 0 | J4: =IFERROR(VLOOKUP(J$10,'Models training data'!$CD$23:$CE$39,2,FALSE),0) -> 0 | ... AQ4: =IFERROR(VLOOKUP(AQ$10,'Models training data'!$CD$23:$CE$39,2,FALSE),0) -> 0
A5: Model 5 | C5: =IFERROR(VLOOKUP(C$10,'Models training data'!$CT$23:$CU$39,2,FALSE),0) -> 11.492466 | D5: =IFERROR(VLOOKUP(D$10,'Models training data'!$CT$23:$CU$39,2,FALSE),0) -> 0 | E5: =IFERROR(VLOOKUP(E$10,'Models training data'!$CT$23:$CU$39,2,FALSE),0) -> 0 | F5: =IFERROR(VLOOKUP(F$10,'Models training data'!$CT$23:$CU$39,2,FALSE),0) -> 0 | G5: =IFERROR(VLOOKUP(G$10,'Models training data'!$CT$23:$CU$39,2,FALSE),0) -> 0 | H5: =IFERROR(VLOOKUP(H$10,'Models training data'!$CT$23:$CU$39,2,FALSE),0) -> 0 | I5: =IFERROR(VLOOKUP(I$10,'Models training data'!$CT$23:$CU$39,2,FALSE),0) -> 0 | J5: =IFERROR(VLOOKUP(J$10,'Models training data'!$CT$23:$CU$39,2,FALSE),0) -> 0 | ... AQ5: =IFERROR(VLOOKUP(AQ$10,'Models training data'!$CT$23:$CU$39,2,FALSE),0) -> 0
A6: Model 6 | C6: =IFERROR(VLOOKUP(C$10,'Models training data'!$DJ$23:$DK$38,2,FALSE),0) -> 101555.06 | D6: =IFERROR(VLOOKUP(D$10,'Models training data'!$DJ$23:$DK$38,2,FALSE),0) -> 0 | E6: =IFERROR(VLOOKUP(E$10,'Models training data'!$DJ$23:$DK$38,2,FALSE),0) -> 0 | F6: =IFERROR(VLOOKUP(F$10,'Models training data'!$DJ$23:$DK$38,2,FALSE),0) -> 0 | G6: =IFERROR(VLOOKUP(G$10,'Models training data'!$DJ$23:$DK$38,2,FALSE),0) -> 0 | H6: =IFERROR(VLOOKUP(H$10,'Models training data'!$DJ$23:$DK$38,2,FALSE),0) -> 0 | I6: =IFERROR(VLOOKUP(I$10,'Models training data'!$DJ$23:$DK$38,2,FALSE),0) -> 0 | J6: =IFERROR(VLOOKUP(J$10,'Models training data'!$DJ$23:$DK$38,2,FALSE),0) -> 0 | ... AQ6: =IFERROR(VLOOKUP(AQ$10,'Models training data'!$DJ$23:$DK$38,2,FALSE),0) -> 0
A7: Model 7 | C7: =IFERROR(VLOOKUP(C$10,'Models training data'!$DZ$23:$EA$38,2,FALSE),0) -> 11.515151 | D7: =IFERROR(VLOOKUP(D$10,'Models training data'!$DZ$23:$EA$38,2,FALSE),0) -> 0 | E7: =IFERROR(VLOOKUP(E$10,'Models training data'!$DZ$23:$EA$38,2,FALSE),0) -> 0 | F7: =IFERROR(VLOOKUP(F$10,'Models training data'!$DZ$23:$EA$38,2,FALSE),0) -> 0 | G7: =IFERROR(VLOOKUP(G$10,'Models training data'!$DZ$23:$EA$38,2,FALSE),0) -> 0 | H7: =IFERROR(VLOOKUP(H$10,'Models training data'!$DZ$23:$EA$38,2,FALSE),0) -> 0 | I7: =IFERROR(VLOOKUP(I$10,'Models training data'!$DZ$23:$EA$38,2,FALSE),0) -> 0 | J7: =IFERROR(VLOOKUP(J$10,'Models training data'!$DZ$23:$EA$38,2,FALSE),0) -> 0 | ... AQ7: =IFERROR(VLOOKUP(AQ$10,'Models training data'!$DZ$23:$EA$38,2,FALSE),0) -> 0
A8: Model 8 | C8: =IFERROR(VLOOKUP(C$10,'Models training data'!$EP$23:$EQ$36,2,FALSE),0) -> 11.319305 | D8: =IFERROR(VLOOKUP(D$10,'Models training data'!$EP$23:$EQ$36,2,FALSE),0) -> 0 | E8: =IFERROR(VLOOKUP(E$10,'Models training data'!$EP$23:$EQ$36,2,FALSE),0) -> 0 | F8: =IFERROR(VLOOKUP(F$10,'Models training data'!$EP$23:$EQ$36,2,FALSE),0) -> 0 | G8: =IFERROR(VLOOKUP(G$10,'Models training data'!$EP$23:$EQ$36,2,FALSE),0) -> 0 | H8: =IFERROR(VLOOKUP(H$10,'Models training data'!$EP$23:$EQ$36,2,FALSE),0) -> 0 | I8: =IFERROR(VLOOKUP(I$10,'Models training data'!$EP$23:$EQ$36,2,FALSE),0) -> 0 | J8: =IFERROR(VLOOKUP(J$10,'Models training data'!$EP$23:$EQ$36,2,FALSE),0) -> 0 | ... AQ8: =IFERROR(VLOOKUP(AQ$10,'Models training data'!$EP$23:$EQ$36,2,FALSE),0) -> -0.084641088
A9: Model 9 | C9: =IFERROR(VLOOKUP(C$10,'Models training data'!FF23:FG38,2,FALSE),0) -> 9.8805996 | D9: =IFERROR(VLOOKUP(D$10,'Models training data'!$FF$23:$FG$40,2,FALSE),0) -> 0 | E9: =IFERROR(VLOOKUP(E$10,'Models training data'!$FF$23:$FG$40,2,FALSE),0) -> 0 | F9: =IFERROR(VLOOKUP(F$10,'Models training data'!$FF$23:$FG$40,2,FALSE),0) -> 0 | G9: =IFERROR(VLOOKUP(G$10,'Models training data'!$FF$23:$FG$40,2,FALSE),0) -> 0 | H9: =IFERROR(VLOOKUP(H$10,'Models training data'!$FF$23:$FG$40,2,FALSE),0) -> 0 | I9: =IFERROR(VLOOKUP(I$10,'Models training data'!$FF$23:$FG$40,2,FALSE),0) -> 0 | J9: =IFERROR(VLOOKUP(J$10,'Models training data'!$FF$23:$FG$40,2,FALSE),0) -> 0 | K9: =IFERROR(VLOOKUP(K$10,'Models training data'!$FF$23:$FG$40,2,FALSE),0) -> 0.00015554873 | ... AA9: =IFERROR(VLOOKUP(AA$10,'Models training data'!$FF$23:$FG$40,2,FALSE),0) -> 0 | AB9: =IFERROR(VLOOKUP(AB$10,'Models training data'!$FF$22:$FG$37,2,FALSE),0) -> -0.023518021 | AC9: =IFERROR(VLOOKUP(AC$10,'Models training data'!$FF$23:$FG$40,2,FALSE),0) -> -0.010830567 | AD9: =IFERROR(VLOOKUP(AD$10,'Models training data'!$FF$23:$FG$40,2,FALSE),0) -> 0.11906675 | AE9: =IFERROR(VLOOKUP(AE$10,'Models training data'!$FF$23:$FG$40,2,FALSE),0) -> 0.12323027 | AF9: =IFERROR(VLOOKUP(AF$10,'Models training data'!$FF$23:$FG$40,2,FALSE),0) -> 0.1630314 | AG9: =IFERROR(VLOOKUP(AG$10,'Models training data'!$FF$23:$FG$40,2,FALSE),0) -> 0 | AH9: =IFERROR(VLOOKUP(AH$10,'Models training data'!$FF$23:$FG$40,2,FALSE),0) -> 0 | AI9: =IFERROR(VLOOKUP(AI$10,'Models training data'!$FF$23:$FG$40,2,FALSE),0) -> 0 | AJ9: =IFERROR(VLOOKUP(AJ$10,'Models training data'!$FF$23:$FG$40,2,FALSE),0) -> 0 | ... AQ9: =IFERROR(VLOOKUP(AQ$10,'Models training data'!$FF$23:$FG$40,2,FALSE),0) -> -0.016895223
A10: Var | C10: Intercept | K10: Sum of count | L10: Sum of count^2 | M10: Sum of ln_count | N10: train | O10: month | P10: Sum of month1 | Q10: Sum of month 2 | R10: Sum of month 3 | S10: Sum of month 4 | T10: Sum of month 5 | U10: Sum of month 6 | V10: Sum of month 7 | W10: Sum of month 8 | X10: Sum of month 9 | Y10: Sum of month 10 | Z10: Sum of month 11 | AA10: Sum of month 12 | AB10: Sum of dum_dl | AC10: Sum of dum_md | AD10: Sum of dum_nj | AE10: Sum of dum_ny | AF10: Sum of dum_pa | AG10: Sum of TV_spend2 | AH10: Sum of Radio_spend2 | AI10: Sum of Youtube_Spend2 | AJ10: Sum of Facebook_Spend_ | AL10: Sum of ln_tv_spend+20%avg | AM10: Sum of ln_radio_spend+20%avg | AN10: Sum of ln_youtube_spend+20%avg | AO10: Sum of ln_facebook_spend+20%avg | AP10: Sum of momth_1_2_3_4_5 | AQ10: Sum of month_6_9_10_11_12
P13: 1 | Q13: 2 | R13: 3 | S13: 4 | T13: 5 | U13: 6 | V13: 7 | W13: 8 | X13: 9 | Y13: 10 | Z13: 11 | AA13: 12 | AB13: DL | AC13: MD | AD13: NJ | AE13: NY | AF13: PA
B14: State | C14: Date | D14: TV_Spend | E14: Radio_Spend | F14: YouTube_spend | G14: =CONCATENATE("Facebook_spend_",Names!$B$6) -> Facebook_spend_ | H14: sales | I14: Total Spend | J14: Year | K14: count | L14: count^2 | M14: ln_count | N14: train | O14: month | P14: month1 | Q14: month 2 | R14: month 3 | S14: month 4 | T14: month 5 | U14: month 6 | V14: month7 | W14: month 8 | X14: month 9 | Y14: month 10 | Z14: month 11 | AA14: month 12 | AB14: dum_dl | AC14: dum_md | AD14: dum_nj | AE14: dum_ny | AF14: dum_pa | AG14: sum of TV_spend | AH14: Sum of Radio_spend | AI14: Sum of Youtube_Spend | AJ14: Sum of Facebook_Spend | AK14: ln_sales | AL14: ln_tv_spend+20%avg | AM14: ln_radio_spend+20%avg | AN14: ln_youtube_spend+20%avg | AO14: ln_facebook_spend+20%avg | AP14: momth_1_2_3_4_5 | AQ14: month_6_9_10_11_12 | AR14: Pred_1 | AS14: Pred_2 | AT14: Pred_3 | AU14: Pred_4 | AV14: Pred_5 | AW14: Pred_6 | AX14: Pred_7 | AY14: Pred_8 | AZ14: Pred_9
B15: NJ | C15: 44562 | D15: 2025 | E15: 400 | F15: 200 | G15: 123.492 | H15: 94403.31 | I15: =SUM(D15:G15) -> 2748.492 | J15: =YEAR(C15) -> 2022 | K15: =IF(B15=B14,K14+1,1) -> 1 | L15: =K15^2 -> 1 | M15: =LN(L15) -> 0 | N15: =IF(K15<127,1,0) -> 1 | O15: =MONTH(C15) -> 1 | P15: =IF($O15=P$13,1,0) -> 1 | Q15: =IF($O15=Q$13,1,0) -> 0 | R15: =IF($O15=R$13,1,0) -> 0 | S15: =IF($O15=S$13,1,0) -> 0 | T15: =IF($O15=T$13,1,0) -> 0 | U15: =IF($O15=U$13,1,0) -> 0 | V15: =IF($O15=V$13,1,0) -> 0 | W15: =IF($O15=W$13,1,0) -> 0 | ... AA15: =IF($O15=AA$13,1,0) -> 0 | AB15: =IF($B15=AB$13,1,0) -> 0 | AC15: =IF($B15=AC$13,1,0) -> 0 | AD15: =IF($B15=AD$13,1,0) -> 1 | AE15: =IF($B15=AE$13,1,0) -> 0 | AF15: =IF($B15=AF$13,1,0) -> 0 | AG15: 2025 | AH15: 400 | AI15: 200 | AJ15: 123.492 | AK15: =LN(H15) -> 11.455331 | AL15: =LN(D15+'Models training data'!$Y$4) -> 7.7476861 | AM15: =LN(E15+'Models training data'!$Y$5) -> 6.1420634 | AN15: =LN(F15+'Models training data'!$Y$6) -> 5.5028019 | AO15: =LN(G15+'Models training data'!$Y$7) -> 5.1538431 | AP15: =V15+W15+X15+Y15+Z15 -> 0 | AQ15: =AA15+AC15+AD15+AE15+AF15 -> 1 | AR15: =$C$1+SUMPRODUCT($K$1:$AQ$1,K15:AQ15) -> 86392.099 | AS15: =$C$2+SUMPRODUCT($K$2:$AQ$2,K15:AQ15) -> 94935.696 | AT15: =$C$3+SUMPRODUCT($K$3:$AQ$3,K15:AQ15) -> 11.450218 | AU15: =$C$4+SUMPRODUCT($K$4:$AQ$4,K15:AQ15) -> 96041.204 | AV15: =$C$5+SUMPRODUCT($K$5:$AQ$5,K15:AQ15) -> 11.466226 | AW15: =$C$6+SUMPRODUCT($K$6:$AQ$6,K15:AQ15) -> 98126.677 | AX15: =$C$7+SUMPRODUCT($K$7:$AQ$7,K15:AQ15) -> 11.487945 | AY15: =$C$8+SUMPRODUCT($K$8:$AQ$8,K15:AQ15) -> 11.474839 | AZ15: =$C$9+SUMPRODUCT($K$9:$AQ$9,K15:AQ15) -> 11.450588
B16: =B15 -> NJ | C16: 44569 | D16: 2055.375 | E16: 410 | F16: 209 | G16: 152.75714 | H16: 96073.235 | I16: =SUM(D16:G16) -> 2827.1321 | J16: =YEAR(C16) -> 2022 | K16: =IF(B16=B15,K15+1,1) -> 2 | L16: =K16^2 -> 4 | M16: =LN(L16) -> 1.3862944 | N16: =IF(K16<127,1,0) -> 1 | O16: =MONTH(C16) -> 1 | P16: =IF($O16=P$13,1,0) -> 1 | Q16: =IF($O16=Q$13,1,0) -> 0 | R16: =IF($O16=R$13,1,0) -> 0 | S16: =IF($O16=S$13,1,0) -> 0 | T16: =IF($O16=T$13,1,0) -> 0 | U16: =IF($O16=U$13,1,0) -> 0 | V16: =IF($O16=V$13,1,0) -> 0 | W16: =IF($O16=W$13,1,0) -> 0 | ... AA16: =IF($O16=AA$13,1,0) -> 0 | AB16: =IF($B16=AB$13,1,0) -> 0 | AC16: =IF($B16=AC$13,1,0) -> 0 | AD16: =IF($B16=AD$13,1,0) -> 1 | AE16: =IF($B16=AE$13,1,0) -> 0 | AF16: =IF($B16=AF$13,1,0) -> 0 | AG16: 2055.375 | AH16: 410 | AI16: 209 | AJ16: 152.75714 | AK16: =LN(H16) -> 11.472866 | AL16: =LN(D16+'Models training data'!$Y$4) -> 7.760715 | AM16: =LN(E16+'Models training data'!$Y$5) -> 6.1633402 | AN16: =LN(F16+'Models training data'!$Y$6) -> 5.5388233 | AO16: =LN(G16+'Models training data'!$Y$7) -> 5.3100511 | AP16: =V16+W16+X16+Y16+Z16 -> 0 | AQ16: =AA16+AC16+AD16+AE16+AF16 -> 1 | AR16: =$C$1+SUMPRODUCT($K$1:$AQ$1,K16:AQ16) -> 86367.709 | AS16: =$C$2+SUMPRODUCT($K$2:$AQ$2,K16:AQ16) -> 94911.598 | AT16: =$C$3+SUMPRODUCT($K$3:$AQ$3,K16:AQ16) -> 11.44996 | AU16: =$C$4+SUMPRODUCT($K$4:$AQ$4,K16:AQ16) -> 95944.094 | AV16: =$C$5+SUMPRODUCT($K$5:$AQ$5,K16:AQ16) -> 11.464917 | AW16: =$C$6+SUMPRODUCT($K$6:$AQ$6,K16:AQ16) -> 97123.758 | AX16: =$C$7+SUMPRODUCT($K$7:$AQ$7,K16:AQ16) -> 11.4764 | AY16: =$C$8+SUMPRODUCT($K$8:$AQ$8,K16:AQ16) -> 11.482071 | AZ16: =$C$9+SUMPRODUCT($K$9:$AQ$9,K16:AQ16) -> 11.474354
B17: =B16 -> NJ | C17: 44576 | D17: 2108.5312 | E17: 425.5 | F17: 219.35 | G17: 139.12511 | H17: 96098.15 | I17: =SUM(D17:G17) -> 2892.5064 | J17: =YEAR(C17) -> 2022 | K17: =IF(B17=B16,K16+1,1) -> 3 | L17: =K17^2 -> 9 | M17: =LN(L17) -> 2.1972246 | N17: =IF(K17<127,1,0) -> 1 | O17: =MONTH(C17) -> 1 | P17: =IF($O17=P$13,1,0) -> 1 | Q17: =IF($O17=Q$13,1,0) -> 0 | R17: =IF($O17=R$13,1,0) -> 0 | S17: =IF($O17=S$13,1,0) -> 0 | T17: =IF($O17=T$13,1,0) -> 0 | U17: =IF($O17=U$13,1,0) -> 0 | V17: =IF($O17=V$13,1,0) -> 0 | W17: =IF($O17=W$13,1,0) -> 0 | ... AA17: =IF($O17=AA$13,1,0) -> 0 | AB17: =IF($B17=AB$13,1,0) -> 0 | AC17: =IF($B17=AC$13,1,0) -> 0 | AD17: =IF($B17=AD$13,1,0) -> 1 | AE17: =IF($B17=AE$13,1,0) -> 0 | AF17: =IF($B17=AF$13,1,0) -> 0 | AG17: 2108.5312 | AH17: 425.5 | AI17: 219.35 | AJ17: 139.12511 | AK17: =LN(H17) -> 11.473125 | AL17: =LN(D17+'Models training data'!$Y$4) -> 7.7831148 | AM17: =LN(E17+'Models training data'!$Y$5) -> 6.1954499 | AN17: =LN(F17+'Models training data'!$Y$6) -> 5.5787047 | AO17: =LN(G17+'Models training data'!$Y$7) -> 5.2403097 | AP17: =V17+W17+X17+Y17+Z17 -> 0 | AQ17: =AA17+AC17+AD17+AE17+AF17 -> 1 | AR17: =$C$1+SUMPRODUCT($K$1:$AQ$1,K17:AQ17) -> 86343.318 | AS17: =$C$2+SUMPRODUCT($K$2:$AQ$2,K17:AQ17) -> 94887.501 | AT17: =$C$3+SUMPRODUCT($K$3:$AQ$3,K17:AQ17) -> 11.449702 | AU17: =$C$4+SUMPRODUCT($K$4:$AQ$4,K17:AQ17) -> 95848.163 | AV17: =$C$5+SUMPRODUCT($K$5:$AQ$5,K17:AQ17) -> 11.463624 | AW17: =$C$6+SUMPRODUCT($K$6:$AQ$6,K17:AQ17) -> 96537.088 | AX17: =$C$7+SUMPRODUCT($K$7:$AQ$7,K17:AQ17) -> 11.469646 | AY17: =$C$8+SUMPRODUCT($K$8:$AQ$8,K17:AQ17) -> 11.483731 | AZ17: =$C$9+SUMPRODUCT($K$9:$AQ$9,K17:AQ17) -> 11.470938
B18: =B17 -> NJ | C18: 44583 | D18: 2179.2291 | E18: 444.275 | F18: 230.3075 | G18: 138.71922 | H18: 96684.372 | I18: =SUM(D18:G18) -> 2992.5308 | J18: =YEAR(C18) -> 2022 | K18: =IF(B18=B17,K17+1,1) -> 4 | L18: =K18^2 -> 16 | M18: =LN(L18) -> 2.7725887 | N18: =IF(K18<127,1,0) -> 1 | O18: =MONTH(C18) -> 1 | P18: =IF($O18=P$13,1,0) -> 1 | Q18: =IF($O18=Q$13,1,0) -> 0 | R18: =IF($O18=R$13,1,0) -> 0 | S18: =IF($O18=S$13,1,0) -> 0 | T18: =IF($O18=T$13,1,0) -> 0 | U18: =IF($O18=U$13,1,0) -> 0 | V18: =IF($O18=V$13,1,0) -> 0 | W18: =IF($O18=W$13,1,0) -> 0 | ... AA18: =IF($O18=AA$13,1,0) -> 0 | AB18: =IF($B18=AB$13,1,0) -> 0 | AC18: =IF($B18=AC$13,1,0) -> 0 | AD18: =IF($B18=AD$13,1,0) -> 1 | AE18: =IF($B18=AE$13,1,0) -> 0 | AF18: =IF($B18=AF$13,1,0) -> 0 | AG18: 2179.2291 | AH18: 444.275 | AI18: 230.3075 | AJ18: 138.71922 | AK18: =LN(H18) -> 11.479207 | AL18: =LN(D18+'Models training data'!$Y$4) -> 7.8121498 | AM18: =LN(E18+'Models training data'!$Y$5) -> 6.2330119 | AN18: =LN(F18+'Models training data'!$Y$6) -> 5.6192625 | AO18: =LN(G18+'Models training data'!$Y$7) -> 5.2381567 | AP18: =V18+W18+X18+Y18+Z18 -> 0 | AQ18: =AA18+AC18+AD18+AE18+AF18 -> 1 | AR18: =$C$1+SUMPRODUCT($K$1:$AQ$1,K18:AQ18) -> 86318.928 | AS18: =$C$2+SUMPRODUCT($K$2:$AQ$2,K18:AQ18) -> 94863.404 | AT18: =$C$3+SUMPRODUCT($K$3:$AQ$3,K18:AQ18) -> 11.449445 | AU18: =$C$4+SUMPRODUCT($K$4:$AQ$4,K18:AQ18) -> 95753.411 | AV18: =$C$5+SUMPRODUCT($K$5:$AQ$5,K18:AQ18) -> 11.462349 | AW18: =$C$6+SUMPRODUCT($K$6:$AQ$6,K18:AQ18) -> 96120.839 | AX18: =$C$7+SUMPRODUCT($K$7:$AQ$7,K18:AQ18) -> 11.464855 | AY18: =$C$8+SUMPRODUCT($K$8:$AQ$8,K18:AQ18) -> 11.488324 | AZ18: =$C$9+SUMPRODUCT($K$9:$AQ$9,K18:AQ18) -> 11.476293
B19: =B18 -> NJ | C19: 44590 | D19: 2263.8804 | E19: 465.23875 | F19: 241.82188 | G19: 153.60006 | H19: 97892.975 | I19: =SUM(D19:G19) -> 3124.5411 | J19: =YEAR(C19) -> 2022 | K19: =IF(B19=B18,K18+1,1) -> 5 | L19: =K19^2 -> 25 | M19: =LN(L19) -> 3.2188758 | N19: =IF(K19<127,1,0) -> 1 | O19: =MONTH(C19) -> 1 | P19: =IF($O19=P$13,1,0) -> 1 | Q19: =IF($O19=Q$13,1,0) -> 0 | R19: =IF($O19=R$13,1,0) -> 0 | S19: =IF($O19=S$13,1,0) -> 0 | T19: =IF($O19=T$13,1,0) -> 0 | U19: =IF($O19=U$13,1,0) -> 0 | V19: =IF($O19=V$13,1,0) -> 0 | W19: =IF($O19=W$13,1,0) -> 0 | ... AA19: =IF($O19=AA$13,1,0) -> 0 | AB19: =IF($B19=AB$13,1,0) -> 0 | AC19: =IF($B19=AC$13,1,0) -> 0 | AD19: =IF($B19=AD$13,1,0) -> 1 | AE19: =IF($B19=AE$13,1,0) -> 0 | AF19: =IF($B19=AF$13,1,0) -> 0 | AG19: 2263.8804 | AH19: 465.23875 | AI19: 241.82188 | AJ19: 153.60006 | AK19: =LN(H19) -> 11.49163 | AL19: =LN(D19+'Models training data'!$Y$4) -> 7.8458416 | AM19: =LN(E19+'Models training data'!$Y$5) -> 6.2733502 | AN19: =LN(F19+'Models training data'!$Y$6) -> 5.6601801 | AO19: =LN(G19+'Models training data'!$Y$7) -> 5.3142079 | AP19: =V19+W19+X19+Y19+Z19 -> 0 | AQ19: =AA19+AC19+AD19+AE19+AF19 -> 1 | AR19: =$C$1+SUMPRODUCT($K$1:$AQ$1,K19:AQ19) -> 86294.538 | AS19: =$C$2+SUMPRODUCT($K$2:$AQ$2,K19:AQ19) -> 94839.306 | AT19: =$C$3+SUMPRODUCT($K$3:$AQ$3,K19:AQ19) -> 11.449187 | AU19: =$C$4+SUMPRODUCT($K$4:$AQ$4,K19:AQ19) -> 95659.838 | AV19: =$C$5+SUMPRODUCT($K$5:$AQ$5,K19:AQ19) -> 11.46109 | AW19: =$C$6+SUMPRODUCT($K$6:$AQ$6,K19:AQ19) -> 95797.971 | AX19: =$C$7+SUMPRODUCT($K$7:$AQ$7,K19:AQ19) -> 11.461138 | AY19: =$C$8+SUMPRODUCT($K$8:$AQ$8,K19:AQ19) -> 11.495967 | AZ19: =$C$9+SUMPRODUCT($K$9:$AQ$9,K19:AQ19) -> 11.491571
B20: =B19 -> NJ | C20: 44597 | D20: 2360.0573 | E20: 487.87569 | F20: 253.91287 | G20: 180.36505 | H20: 99097.406 | I20: =SUM(D20:G20) -> 3282.2109 | J20: =YEAR(C20) -> 2022 | K20: =IF(B20=B19,K19+1,1) -> 6 | L20: =K20^2 -> 36 | M20: =LN(L20) -> 3.5835189 | N20: =IF(K20<127,1,0) -> 1 | O20: =MONTH(C20) -> 2 | P20: =IF($O20=P$13,1,0) -> 0 | Q20: =IF($O20=Q$13,1,0) -> 1 | R20: =IF($O20=R$13,1,0) -> 0 | S20: =IF($O20=S$13,1,0) -> 0 | T20: =IF($O20=T$13,1,0) -> 0 | U20: =IF($O20=U$13,1,0) -> 0 | V20: =IF($O20=V$13,1,0) -> 0 | W20: =IF($O20=W$13,1,0) -> 0 | ... AA20: =IF($O20=AA$13,1,0) -> 0 | AB20: =IF($B20=AB$13,1,0) -> 0 | AC20: =IF($B20=AC$13,1,0) -> 0 | AD20: =IF($B20=AD$13,1,0) -> 1 | AE20: =IF($B20=AE$13,1,0) -> 0 | AF20: =IF($B20=AF$13,1,0) -> 0 | AG20: 2360.0573 | AH20: 487.87569 | AI20: 253.91287 | AJ20: 180.36505 | AK20: =LN(H20) -> 11.503859 | AL20: =LN(D20+'Models training data'!$Y$4) -> 7.8827918 | AM20: =LN(E20+'Models training data'!$Y$5) -> 6.315155 | AN20: =LN(F20+'Models training data'!$Y$6) -> 5.7014175 | AO20: =LN(G20+'Models training data'!$Y$7) -> 5.4379423 | AP20: =V20+W20+X20+Y20+Z20 -> 0 | AQ20: =AA20+AC20+AD20+AE20+AF20 -> 1 | AR20: =$C$1+SUMPRODUCT($K$1:$AQ$1,K20:AQ20) -> 85220.436 | AS20: =$C$2+SUMPRODUCT($K$2:$AQ$2,K20:AQ20) -> 93763.098 | AT20: =$C$3+SUMPRODUCT($K$3:$AQ$3,K20:AQ20) -> 11.437235 | AU20: =$C$4+SUMPRODUCT($K$4:$AQ$4,K20:AQ20) -> 94635.478 | AV20: =$C$5+SUMPRODUCT($K$5:$AQ$5,K20:AQ20) -> 11.4499 | AW20: =$C$6+SUMPRODUCT($K$6:$AQ$6,K20:AQ20) -> 95091.862 | AX20: =$C$7+SUMPRODUCT($K$7:$AQ$7,K20:AQ20) -> 11.453589 | AY20: =$C$8+SUMPRODUCT($K$8:$AQ$8,K20:AQ20) -> 11.506003 | AZ20: =$C$9+SUMPRODUCT($K$9:$AQ$9,K20:AQ20) -> 11.512903
B21: =B20 -> NJ | C21: 44604 | D21: 2466.1482 | E21: 511.95697 | F21: 266.6085 | G21: 155.09789 | H21: 98883.709 | I21: =SUM(D21:G21) -> 3399.8116 | J21: =YEAR(C21) -> 2022 | K21: =IF(B21=B20,K20+1,1) -> 7 | L21: =K21^2 -> 49 | M21: =LN(L21) -> 3.8918203 | N21: =IF(K21<127,1,0) -> 1 | O21: =MONTH(C21) -> 2 | P21: =IF($O21=P$13,1,0) -> 0 | Q21: =IF($O21=Q$13,1,0) -> 1 | R21: =IF($O21=R$13,1,0) -> 0 | S21: =IF($O21=S$13,1,0) -> 0 | T21: =IF($O21=T$13,1,0) -> 0 | U21: =IF($O21=U$13,1,0) -> 0 | V21: =IF($O21=V$13,1,0) -> 0 | W21: =IF($O21=W$13,1,0) -> 0 | ... AA21: =IF($O21=AA$13,1,0) -> 0 | AB21: =IF($B21=AB$13,1,0) -> 0 | AC21: =IF($B21=AC$13,1,0) -> 0 | AD21: =IF($B21=AD$13,1,0) -> 1 | AE21: =IF($B21=AE$13,1,0) -> 0 | AF21: =IF($B21=AF$13,1,0) -> 0 | AG21: 2466.1482 | AH21: 511.95697 | AI21: 266.6085 | AJ21: 155.09789 | AK21: =LN(H21) -> 11.5017 | AL21: =LN(D21+'Models training data'!$Y$4) -> 7.9220272 | AM21: =LN(E21+'Models training data'!$Y$5) -> 6.3577886 | AN21: =LN(F21+'Models training data'!$Y$6) -> 5.7429615 | AO21: =LN(G21+'Models training data'!$Y$7) -> 5.321552 | AP21: =V21+W21+X21+Y21+Z21 -> 0 | AQ21: =AA21+AC21+AD21+AE21+AF21 -> 1 | AR21: =$C$1+SUMPRODUCT($K$1:$AQ$1,K21:AQ21) -> 85196.046 | AS21: =$C$2+SUMPRODUCT($K$2:$AQ$2,K21:AQ21) -> 93739.001 | AT21: =$C$3+SUMPRODUCT($K$3:$AQ$3,K21:AQ21) -> 11.436978 | AU21: =$C$4+SUMPRODUCT($K$4:$AQ$4,K21:AQ21) -> 94544.262 | AV21: =$C$5+SUMPRODUCT($K$5:$AQ$5,K21:AQ21) -> 11.448675 | AW21: =$C$6+SUMPRODUCT($K$6:$AQ$6,K21:AQ21) -> 94868.82 | AX21: =$C$7+SUMPRODUCT($K$7:$AQ$7,K21:AQ21) -> 11.451021 | AY21: =$C$8+SUMPRODUCT($K$8:$AQ$8,K21:AQ21) -> 11.508179 | AZ21: =$C$9+SUMPRODUCT($K$9:$AQ$9,K21:AQ21) -> 11.50447
B22: =B21 -> NJ | C22: 44611 | D22: 2581.1173 | E22: 537.39857 | F22: 279.93893 | G22: 203.85299 | H22: 101098.12 | I22: =SUM(D22:G22) -> 3602.3078 | J22: =YEAR(C22) -> 2022 | K22: =IF(B22=B21,K21+1,1) -> 8 | L22: =K22^2 -> 64 | M22: =LN(L22) -> 4.1588831 | N22: =IF(K22<127,1,0) -> 1 | O22: =MONTH(C22) -> 2 | P22: =IF($O22=P$13,1,0) -> 0 | Q22: =IF($O22=Q$13,1,0) -> 1 | R22: =IF($O22=R$13,1,0) -> 0 | S22: =IF($O22=S$13,1,0) -> 0 | T22: =IF($O22=T$13,1,0) -> 0 | U22: =IF($O22=U$13,1,0) -> 0 | V22: =IF($O22=V$13,1,0) -> 0 | W22: =IF($O22=W$13,1,0) -> 0 | ... AA22: =IF($O22=AA$13,1,0) -> 0 | AB22: =IF($B22=AB$13,1,0) -> 0 | AC22: =IF($B22=AC$13,1,0) -> 0 | AD22: =IF($B22=AD$13,1,0) -> 1 | AE22: =IF($B22=AE$13,1,0) -> 0 | AF22: =IF($B22=AF$13,1,0) -> 0 | AG22: 2581.1173 | AH22: 537.39857 | AI22: 279.93893 | AJ22: 203.85299 | AK22: =LN(H22) -> 11.523847 | AL22: =LN(D22+'Models training data'!$Y$4) -> 7.9628767 | AM22: =LN(E22+'Models training data'!$Y$5) -> 6.4009394 | AN22: =LN(F22+'Models training data'!$Y$6) -> 5.7848014 | AO22: =LN(G22+'Models training data'!$Y$7) -> 5.5351919 | AP22: =V22+W22+X22+Y22+Z22 -> 0 | AQ22: =AA22+AC22+AD22+AE22+AF22 -> 1 | AR22: =$C$1+SUMPRODUCT($K$1:$AQ$1,K22:AQ22) -> 85171.656 | AS22: =$C$2+SUMPRODUCT($K$2:$AQ$2,K22:AQ22) -> 93714.903 | AT22: =$C$3+SUMPRODUCT($K$3:$AQ$3,K22:AQ22) -> 11.43672 | AU22: =$C$4+SUMPRODUCT($K$4:$AQ$4,K22:AQ22) -> 94454.225 | AV22: =$C$5+SUMPRODUCT($K$5:$AQ$5,K22:AQ22) -> 11.447467 | AW22: =$C$6+SUMPRODUCT($K$6:$AQ$6,K22:AQ22) -> 94675.613 | AX22: =$C$7+SUMPRODUCT($K$7:$AQ$7,K22:AQ22) -> 11.448797 | AY22: =$C$8+SUMPRODUCT($K$8:$AQ$8,K22:AQ22) -> 11.522571 | AZ22: =$C$9+SUMPRODUCT($K$9:$AQ$9,K22:AQ22) -> 11.53713
B23: =B22 -> NJ | C23: 44618 | D23: 2704.3363 | E23: 564.19037 | F23: 293.93587 | G23: 217.17695 | H23: 102116.02 | I23: =SUM(D23:G23) -> 3779.6395 | J23: =YEAR(C23) -> 2022 | K23: =IF(B23=B22,K22+1,1) -> 9 | L23: =K23^2 -> 81 | M23: =LN(L23) -> 4.3944492 | N23: =IF(K23<127,1,0) -> 1 | O23: =MONTH(C23) -> 2 | P23: =IF($O23=P$13,1,0) -> 0 | Q23: =IF($O23=Q$13,1,0) -> 1 | R23: =IF($O23=R$13,1,0) -> 0 | S23: =IF($O23=S$13,1,0) -> 0 | T23: =IF($O23=T$13,1,0) -> 0 | U23: =IF($O23=U$13,1,0) -> 0 | V23: =IF($O23=V$13,1,0) -> 0 | W23: =IF($O23=W$13,1,0) -> 0 | ... AA23: =IF($O23=AA$13,1,0) -> 0 | AB23: =IF($B23=AB$13,1,0) -> 0 | AC23: =IF($B23=AC$13,1,0) -> 0 | AD23: =IF($B23=AD$13,1,0) -> 1 | AE23: =IF($B23=AE$13,1,0) -> 0 | AF23: =IF($B23=AF$13,1,0) -> 0 | AG23: 2704.3363 | AH23: 564.19037 | AI23: 293.93587 | AJ23: 217.17695 | AK23: =LN(H23) -> 11.533865 | AL23: =LN(D23+'Models training data'!$Y$4) -> 8.0048808 | AM23: =LN(E23+'Models training data'!$Y$5) -> 6.4444531 | AN23: =LN(F23+'Models training data'!$Y$6) -> 5.826927 | AO23: =LN(G23+'Models training data'!$Y$7) -> 5.5864258 | AP23: =V23+W23+X23+Y23+Z23 -> 0 | AQ23: =AA23+AC23+AD23+AE23+AF23 -> 1 | AR23: =$C$1+SUMPRODUCT($K$1:$AQ$1,K23:AQ23) -> 85147.265 | AS23: =$C$2+SUMPRODUCT($K$2:$AQ$2,K23:AQ23) -> 93690.806 | AT23: =$C$3+SUMPRODUCT($K$3:$AQ$3,K23:AQ23) -> 11.436462 | AU23: =$C$4+SUMPRODUCT($K$4:$AQ$4,K23:AQ23) -> 94365.366 | AV23: =$C$5+SUMPRODUCT($K$5:$AQ$5,K23:AQ23) -> 11.446276 | AW23: =$C$6+SUMPRODUCT($K$6:$AQ$6,K23:AQ23) -> 94505.192 | AX23: =$C$7+SUMPRODUCT($K$7:$AQ$7,K23:AQ23) -> 11.446836 | AY23: =$C$8+SUMPRODUCT($K$8:$AQ$8,K23:AQ23) -> 11.531709 | AZ23: =$C$9+SUMPRODUCT($K$9:$AQ$9,K23:AQ23) -> 11.549653
B24: =B23 -> NJ | C24: 44625 | D24: 2835.4673 | E24: 592.36083 | F24: 308.63267 | G24: 223.61963 | H24: 102941.19 | I24: =SUM(D24:G24) -> 3960.0804 | J24: =YEAR(C24) -> 2022 | K24: =IF(B24=B23,K23+1,1) -> 10 | L24: =K24^2 -> 100 | M24: =LN(L24) -> 4.6051702 | N24: =IF(K24<127,1,0) -> 1 | O24: =MONTH(C24) -> 3 | P24: =IF($O24=P$13,1,0) -> 0 | Q24: =IF($O24=Q$13,1,0) -> 0 | R24: =IF($O24=R$13,1,0) -> 1 | S24: =IF($O24=S$13,1,0) -> 0 | T24: =IF($O24=T$13,1,0) -> 0 | U24: =IF($O24=U$13,1,0) -> 0 | V24: =IF($O24=V$13,1,0) -> 0 | W24: =IF($O24=W$13,1,0) -> 0 | ... AA24: =IF($O24=AA$13,1,0) -> 0 | AB24: =IF($B24=AB$13,1,0) -> 0 | AC24: =IF($B24=AC$13,1,0) -> 0 | AD24: =IF($B24=AD$13,1,0) -> 1 | AE24: =IF($B24=AE$13,1,0) -> 0 | AF24: =IF($B24=AF$13,1,0) -> 0 | AG24: 2835.4673 | AH24: 592.36083 | AI24: 308.63267 | AJ24: 223.61963 | AK24: =LN(H24) -> 11.541913 | AL24: =LN(D24+'Models training data'!$Y$4) -> 8.0477251 | AM24: =LN(E24+'Models training data'!$Y$5) -> 6.4882515 | AN24: =LN(F24+'Models training data'!$Y$6) -> 5.8693284 | AO24: =LN(G24+'Models training data'!$Y$7) -> 5.6102886 | AP24: =V24+W24+X24+Y24+Z24 -> 0 | AQ24: =AA24+AC24+AD24+AE24+AF24 -> 1 | AR24: =$C$1+SUMPRODUCT($K$1:$AQ$1,K24:AQ24) -> 84207.664 | AS24: =$C$2+SUMPRODUCT($K$2:$AQ$2,K24:AQ24) -> 92749.098 | AT24: =$C$3+SUMPRODUCT($K$3:$AQ$3,K24:AQ24) -> 11.425398 | AU24: =$C$4+SUMPRODUCT($K$4:$AQ$4,K24:AQ24) -> 93316.08 | AV24: =$C$5+SUMPRODUCT($K$5:$AQ$5,K24:AQ24) -> 11.433681 | AW24: =$C$6+SUMPRODUCT($K$6:$AQ$6,K24:AQ24) -> 93605.781 | AX24: =$C$7+SUMPRODUCT($K$7:$AQ$7,K24:AQ24) -> 11.4364 | AY24: =$C$8+SUMPRODUCT($K$8:$AQ$8,K24:AQ24) -> 11.540147 | AZ24: =$C$9+SUMPRODUCT($K$9:$AQ$9,K24:AQ24) -> 11.558819
B25: =B24 -> NJ | C25: 44632 | D25: 2974.3806 | E25: 621.95934 | F25: 324.0643 | G25: 202.337 | H25: 103029.42 | I25: =SUM(D25:G25) -> 4122.7412 | J25: =YEAR(C25) -> 2022 | K25: =IF(B25=B24,K24+1,1) -> 11 | L25: =K25^2 -> 121 | M25: =LN(L25) -> 4.7957905 | N25: =IF(K25<127,1,0) -> 1 | O25: =MONTH(C25) -> 3 | P25: =IF($O25=P$13,1,0) -> 0 | Q25: =IF($O25=Q$13,1,0) -> 0 | R25: =IF($O25=R$13,1,0) -> 1 | S25: =IF($O25=S$13,1,0) -> 0 | T25: =IF($O25=T$13,1,0) -> 0 | U25: =IF($O25=U$13,1,0) -> 0 | V25: =IF($O25=V$13,1,0) -> 0 | W25: =IF($O25=W$13,1,0) -> 0 | ... AA25: =IF($O25=AA$13,1,0) -> 0 | AB25: =IF($B25=AB$13,1,0) -> 0 | AC25: =IF($B25=AC$13,1,0) -> 0 | AD25: =IF($B25=AD$13,1,0) -> 1 | AE25: =IF($B25=AE$13,1,0) -> 0 | AF25: =IF($B25=AF$13,1,0) -> 0 | AG25: 2974.3806 | AH25: 621.95934 | AI25: 324.0643 | AJ25: 202.337 | AK25: =LN(H25) -> 11.54277 | AL25: =LN(D25+'Models training data'!$Y$4) -> 8.0911949 | AM25: =LN(E25+'Models training data'!$Y$5) -> 6.5322927 | AN25: =LN(F25+'Models training data'!$Y$6) -> 5.9119959 | AO25: =LN(G25+'Models training data'!$Y$7) -> 5.5291927 | AP25: =V25+W25+X25+Y25+Z25 -> 0 | AQ25: =AA25+AC25+AD25+AE25+AF25 -> 1 | AR25: =$C$1+SUMPRODUCT($K$1:$AQ$1,K25:AQ25) -> 84183.274 | AS25: =$C$2+SUMPRODUCT($K$2:$AQ$2,K25:AQ25) -> 92725.001 | AT25: =$C$3+SUMPRODUCT($K$3:$AQ$3,K25:AQ25) -> 11.42514 | AU25: =$C$4+SUMPRODUCT($K$4:$AQ$4,K25:AQ25) -> 93229.579 | AV25: =$C$5+SUMPRODUCT($K$5:$AQ$5,K25:AQ25) -> 11.432524 | AW25: =$C$6+SUMPRODUCT($K$6:$AQ$6,K25:AQ25) -> 93467.876 | AX25: =$C$7+SUMPRODUCT($K$7:$AQ$7,K25:AQ25) -> 11.434812 | AY25: =$C$8+SUMPRODUCT($K$8:$AQ$8,K25:AQ25) -> 11.544566 | AZ25: =$C$9+SUMPRODUCT($K$9:$AQ$9,K25:AQ25) -> 11.554976
B26: =B25 -> NJ | C26: 44639 | D26: 3121.0976 | E26: 653.04754 | F26: 340.26751 | G26: 225.30118 | H26: 104303.66 | I26: =SUM(D26:G26) -> 4339.7138 | J26: =YEAR(C26) -> 2022 | K26: =IF(B26=B25,K25+1,1) -> 12 | L26: =K26^2 -> 144 | M26: =LN(L26) -> 4.9698133 | N26: =IF(K26<127,1,0) -> 1 | O26: =MONTH(C26) -> 3 | P26: =IF($O26=P$13,1,0) -> 0 | Q26: =IF($O26=Q$13,1,0) -> 0 | R26: =IF($O26=R$13,1,0) -> 1 | S26: =IF($O26=S$13,1,0) -> 0 | T26: =IF($O26=T$13,1,0) -> 0 | U26: =IF($O26=U$13,1,0) -> 0 | V26: =IF($O26=V$13,1,0) -> 0 | W26: =IF($O26=W$13,1,0) -> 0 | ... AA26: =IF($O26=AA$13,1,0) -> 0 | AB26: =IF($B26=AB$13,1,0) -> 0 | AC26: =IF($B26=AC$13,1,0) -> 0 | AD26: =IF($B26=AD$13,1,0) -> 1 | AE26: =IF($B26=AE$13,1,0) -> 0 | AF26: =IF($B26=AF$13,1,0) -> 0 | AG26: 3121.0976 | AH26: 653.04754 | AI26: 340.26751 | AJ26: 225.30118 | AK26: =LN(H26) -> 11.555062 | AL26: =LN(D26+'Models training data'!$Y$4) -> 8.1351431 | AM26: =LN(E26+'Models training data'!$Y$5) -> 6.5765526 | AN26: =LN(F26+'Models training data'!$Y$6) -> 5.9549198 | AO26: =LN(G26+'Models training data'!$Y$7) -> 5.6164242 | AP26: =V26+W26+X26+Y26+Z26 -> 0 | AQ26: =AA26+AC26+AD26+AE26+AF26 -> 1 | AR26: =$C$1+SUMPRODUCT($K$1:$AQ$1,K26:AQ26) -> 84158.884 | AS26: =$C$2+SUMPRODUCT($K$2:$AQ$2,K26:AQ26) -> 92700.903 | AT26: =$C$3+SUMPRODUCT($K$3:$AQ$3,K26:AQ26) -> 11.424882 | AU26: =$C$4+SUMPRODUCT($K$4:$AQ$4,K26:AQ26) -> 93144.256 | AV26: =$C$5+SUMPRODUCT($K$5:$AQ$5,K26:AQ26) -> 11.431384 | AW26: =$C$6+SUMPRODUCT($K$6:$AQ$6,K26:AQ26) -> 93341.979 | AX26: =$C$7+SUMPRODUCT($K$7:$AQ$7,K26:AQ26) -> 11.433363 | AY26: =$C$8+SUMPRODUCT($K$8:$AQ$8,K26:AQ26) -> 11.556457 | AZ26: =$C$9+SUMPRODUCT($K$9:$AQ$9,K26:AQ26) -> 11.572096
B27: =B26 -> NJ | C27: 44646 | D27: 3275.751 | E27: 685.69504 | F27: 357.28089 | G27: 241.64169 | H27: 105364.32 | I27: =SUM(D27:G27) -> 4560.3686 | J27: =YEAR(C27) -> 2022 | K27: =IF(B27=B26,K26+1,1) -> 13 | L27: =K27^2 -> 169 | M27: =LN(L27) -> 5.1298987 | N27: =IF(K27<127,1,0) -> 1 | O27: =MONTH(C27) -> 3 | P27: =IF($O27=P$13,1,0) -> 0 | Q27: =IF($O27=Q$13,1,0) -> 0 | R27: =IF($O27=R$13,1,0) -> 1 | S27: =IF($O27=S$13,1,0) -> 0 | T27: =IF($O27=T$13,1,0) -> 0 | U27: =IF($O27=U$13,1,0) -> 0 | V27: =IF($O27=V$13,1,0) -> 0 | W27: =IF($O27=W$13,1,0) -> 0 | ... AA27: =IF($O27=AA$13,1,0) -> 0 | AB27: =IF($B27=AB$13,1,0) -> 0 | AC27: =IF($B27=AC$13,1,0) -> 0 | AD27: =IF($B27=AD$13,1,0) -> 1 | AE27: =IF($B27=AE$13,1,0) -> 0 | AF27: =IF($B27=AF$13,1,0) -> 0 | AG27: 3275.751 | AH27: 685.69504 | AI27: 357.28089 | AJ27: 241.64169 | AK27: =LN(H27) -> 11.565179 | AL27: =LN(D27+'Models training data'!$Y$4) -> 8.1794683 | AM27: =LN(E27+'Models training data'!$Y$5) -> 6.6210156 | AN27: =LN(F27+'Models training data'!$Y$6) -> 5.998091 | AO27: =LN(G27+'Models training data'!$Y$7) -> 5.6741653 | AP27: =V27+W27+X27+Y27+Z27 -> 0 | AQ27: =AA27+AC27+AD27+AE27+AF27 -> 1 | AR27: =$C$1+SUMPRODUCT($K$1:$AQ$1,K27:AQ27) -> 84134.493 | AS27: =$C$2+SUMPRODUCT($K$2:$AQ$2,K27:AQ27) -> 92676.806 | AT27: =$C$3+SUMPRODUCT($K$3:$AQ$3,K27:AQ27) -> 11.424625 | AU27: =$C$4+SUMPRODUCT($K$4:$AQ$4,K27:AQ27) -> 93060.112 | AV27: =$C$5+SUMPRODUCT($K$5:$AQ$5,K27:AQ27) -> 11.430261 | AW27: =$C$6+SUMPRODUCT($K$6:$AQ$6,K27:AQ27) -> 93226.165 | AX27: =$C$7+SUMPRODUCT($K$7:$AQ$7,K27:AQ27) -> 11.43203 | AY27: =$C$8+SUMPRODUCT($K$8:$AQ$8,K27:AQ27) -> 11.567721 | AZ27: =$C$9+SUMPRODUCT($K$9:$AQ$9,K27:AQ27) -> 11.585584
... B171: =B170 -> NJ | C171: 45654 | D171: 1256.8316 | E171: 251.51938 | F171: 126.86524 | G171: 91.913501 | H171: 89534.355 | I171: =SUM(D171:G171) -> 1727.1297 | J171: =YEAR(C171) -> 2024 | K171: =IF(B171=B170,K170+1,1) -> 157 | L171: =K171^2 -> 24649 | M171: =LN(L171) -> 10.112492 | N171: =IF(K171<127,1,0) -> 0 | O171: =MONTH(C171) -> 12 | P171: =IF($O171=P$13,1,0) -> 0 | Q171: =IF($O171=Q$13,1,0) -> 0 | R171: =IF($O171=R$13,1,0) -> 0 | S171: =IF($O171=S$13,1,0) -> 0 | T171: =IF($O171=T$13,1,0) -> 0 | U171: =IF($O171=U$13,1,0) -> 0 | V171: =IF($O171=V$13,1,0) -> 0 | W171: =IF($O171=W$13,1,0) -> 0 | ... AA171: =IF($O171=AA$13,1,0) -> 1 | AB171: =IF($B171=AB$13,1,0) -> 0 | AC171: =IF($B171=AC$13,1,0) -> 0 | AD171: =IF($B171=AD$13,1,0) -> 1 | AE171: =IF($B171=AE$13,1,0) -> 0 | AF171: =IF($B171=AF$13,1,0) -> 0 | AG171: 1256.8316 | AH171: 251.51938 | AI171: 126.86524 | AJ171: 91.913501 | AK171: =LN(H171) -> 11.402378 | AL171: =LN(D171+'Models training data'!$Y$4) -> 7.3447438 | AM171: =LN(E171+'Models training data'!$Y$5) -> 5.7574226 | AN171: =LN(F171+'Models training data'!$Y$6) -> 5.1489105 | AO171: =LN(G171+'Models training data'!$Y$7) -> 4.9524194 | AP171: =V171+W171+X171+Y171+Z171 -> 0 | AQ171: =AA171+AC171+AD171+AE171+AF171 -> 2 | AR171: =$C$1+SUMPRODUCT($K$1:$AQ$1,K171:AQ171) -> 81456.478 | AS171: =$C$2+SUMPRODUCT($K$2:$AQ$2,K171:AQ171) -> 90038.245 | AT171: =$C$3+SUMPRODUCT($K$3:$AQ$3,K171:AQ171) -> 11.395954 | AU171: =$C$4+SUMPRODUCT($K$4:$AQ$4,K171:AQ171) -> 94688.864 | AV171: =$C$5+SUMPRODUCT($K$5:$AQ$5,K171:AQ171) -> 11.462628 | AW171: =$C$6+SUMPRODUCT($K$6:$AQ$6,K171:AQ171) -> 90847.277 | AX171: =$C$7+SUMPRODUCT($K$7:$AQ$7,K171:AQ171) -> 11.403685 | AY171: =$C$8+SUMPRODUCT($K$8:$AQ$8,K171:AQ171) -> 11.329816 | AZ171: =$C$9+SUMPRODUCT($K$9:$AQ$9,K171:AQ171) -> 11.381172
B172: NY | C172: 44562 | D172: 4050 | E172: 800 | F172: 400 | G172: 283.73677 | H172: 111249.41 | I172: =SUM(D172:G172) -> 5533.7368 | J172: =YEAR(C172) -> 2022 | K172: =IF(B172=B171,K171+1,1) -> 1 | L172: =K172^2 -> 1 | M172: =LN(L172) -> 0 | N172: =IF(K172<127,1,0) -> 1 | O172: =MONTH(C172) -> 1 | P172: =IF($O172=P$13,1,0) -> 1 | Q172: =IF($O172=Q$13,1,0) -> 0 | R172: =IF($O172=R$13,1,0) -> 0 | S172: =IF($O172=S$13,1,0) -> 0 | T172: =IF($O172=T$13,1,0) -> 0 | U172: =IF($O172=U$13,1,0) -> 0 | V172: =IF($O172=V$13,1,0) -> 0 | W172: =IF($O172=W$13,1,0) -> 0 | ... AA172: =IF($O172=AA$13,1,0) -> 0 | AB172: =IF($B172=AB$13,1,0) -> 0 | AC172: =IF($B172=AC$13,1,0) -> 0 | AD172: =IF($B172=AD$13,1,0) -> 0 | AE172: =IF($B172=AE$13,1,0) -> 1 | AF172: =IF($B172=AF$13,1,0) -> 0 | AG172: 4050 | AH172: 800 | AI172: 400 | AJ172: 283.73677 | AK172: =LN(H172) -> 11.61953 | AL172: =LN(D172+'Models training data'!$Y$4) -> 8.3759076 | AM172: =LN(E172+'Models training data'!$Y$5) -> 6.7627435 | AN172: =LN(F172+'Models training data'!$Y$6) -> 6.0989244 | AO172: =LN(G172+'Models training data'!$Y$7) -> 5.8091636 | AP172: =V172+W172+X172+Y172+Z172 -> 0 | AQ172: =AA172+AC172+AD172+AE172+AF172 -> 1 | AR172: =$C$1+SUMPRODUCT($K$1:$AQ$1,K172:AQ172) -> 86392.099 | AS172: =$C$2+SUMPRODUCT($K$2:$AQ$2,K172:AQ172) -> 110385.63 | AT172: =$C$3+SUMPRODUCT($K$3:$AQ$3,K172:AQ172) -> 11.599395 | AU172: =$C$4+SUMPRODUCT($K$4:$AQ$4,K172:AQ172) -> 111491.14 | AV172: =$C$5+SUMPRODUCT($K$5:$AQ$5,K172:AQ172) -> 11.615403 | AW172: =$C$6+SUMPRODUCT($K$6:$AQ$6,K172:AQ172) -> 113576.61 | AX172: =$C$7+SUMPRODUCT($K$7:$AQ$7,K172:AQ172) -> 11.637121 | AY172: =$C$8+SUMPRODUCT($K$8:$AQ$8,K172:AQ172) -> 11.659233 | AZ172: =$C$9+SUMPRODUCT($K$9:$AQ$9,K172:AQ172) -> 11.621665
B173: =B172 -> NY | C173: 44569 | D173: 4110.75 | E173: 820 | F173: 418 | G173: 291.26661 | H173: 111854.26 | I173: =SUM(D173:G173) -> 5640.0166 | J173: =YEAR(C173) -> 2022 | K173: =IF(B173=B172,K172+1,1) -> 2 | L173: =K173^2 -> 4 | M173: =LN(L173) -> 1.3862944 | N173: =IF(K173<127,1,0) -> 1 | O173: =MONTH(C173) -> 1 | P173: =IF($O173=P$13,1,0) -> 1 | Q173: =IF($O173=Q$13,1,0) -> 0 | R173: =IF($O173=R$13,1,0) -> 0 | S173: =IF($O173=S$13,1,0) -> 0 | T173: =IF($O173=T$13,1,0) -> 0 | U173: =IF($O173=U$13,1,0) -> 0 | V173: =IF($O173=V$13,1,0) -> 0 | W173: =IF($O173=W$13,1,0) -> 0 | ... AA173: =IF($O173=AA$13,1,0) -> 0 | AB173: =IF($B173=AB$13,1,0) -> 0 | AC173: =IF($B173=AC$13,1,0) -> 0 | AD173: =IF($B173=AD$13,1,0) -> 0 | AE173: =IF($B173=AE$13,1,0) -> 1 | AF173: =IF($B173=AF$13,1,0) -> 0 | AG173: 4110.75 | AH173: 820 | AI173: 418 | AJ173: 291.26661 | AK173: =LN(H173) -> 11.624952 | AL173: =LN(D173+'Models training data'!$Y$4) -> 8.3898044 | AM173: =LN(E173+'Models training data'!$Y$5) -> 6.7856013 | AN173: =LN(F173+'Models training data'!$Y$6) -> 6.1385442 | AO173: =LN(G173+'Models training data'!$Y$7) -> 5.8315013 | AP173: =V173+W173+X173+Y173+Z173 -> 0 | AQ173: =AA173+AC173+AD173+AE173+AF173 -> 1 | AR173: =$C$1+SUMPRODUCT($K$1:$AQ$1,K173:AQ173) -> 86367.709 | AS173: =$C$2+SUMPRODUCT($K$2:$AQ$2,K173:AQ173) -> 110361.53 | AT173: =$C$3+SUMPRODUCT($K$3:$AQ$3,K173:AQ173) -> 11.599137 | AU173: =$C$4+SUMPRODUCT($K$4:$AQ$4,K173:AQ173) -> 111394.03 | AV173: =$C$5+SUMPRODUCT($K$5:$AQ$5,K173:AQ173) -> 11.614094 | AW173: =$C$6+SUMPRODUCT($K$6:$AQ$6,K173:AQ173) -> 112573.69 | AX173: =$C$7+SUMPRODUCT($K$7:$AQ$7,K173:AQ173) -> 11.625577 | AY173: =$C$8+SUMPRODUCT($K$8:$AQ$8,K173:AQ173) -> 11.665654 | AZ173: =$C$9+SUMPRODUCT($K$9:$AQ$9,K173:AQ173) -> 11.629178
B174: =B173 -> NY | C174: 44576 | D174: 4217.0625 | E174: 851 | F174: 438.7 | G174: 320.78537 | H174: 112964.4 | I174: =SUM(D174:G174) -> 5827.5479 | J174: =YEAR(C174) -> 2022 | K174: =IF(B174=B173,K173+1,1) -> 3 | L174: =K174^2 -> 9 | M174: =LN(L174) -> 2.1972246 | N174: =IF(K174<127,1,0) -> 1 | O174: =MONTH(C174) -> 1 | P174: =IF($O174=P$13,1,0) -> 1 | Q174: =IF($O174=Q$13,1,0) -> 0 | R174: =IF($O174=R$13,1,0) -> 0 | S174: =IF($O174=S$13,1,0) -> 0 | T174: =IF($O174=T$13,1,0) -> 0 | U174: =IF($O174=U$13,1,0) -> 0 | V174: =IF($O174=V$13,1,0) -> 0 | W174: =IF($O174=W$13,1,0) -> 0 | ... AA174: =IF($O174=AA$13,1,0) -> 0 | AB174: =IF($B174=AB$13,1,0) -> 0 | AC174: =IF($B174=AC$13,1,0) -> 0 | AD174: =IF($B174=AD$13,1,0) -> 0 | AE174: =IF($B174=AE$13,1,0) -> 1 | AF174: =IF($B174=AF$13,1,0) -> 0 | AG174: 4217.0625 | AH174: 851 | AI174: 438.7 | AJ174: 320.78537 | AK174: =LN(H174) -> 11.634828 | AL174: =LN(D174+'Models training data'!$Y$4) -> 8.4136686 | AM174: =LN(E174+'Models training data'!$Y$5) -> 6.8200296 | AN174: =LN(F174+'Models training data'!$Y$6) -> 6.1822471 | AO174: =LN(G174+'Models training data'!$Y$7) -> 5.9145533 | AP174: =V174+W174+X174+Y174+Z174 -> 0 | AQ174: =AA174+AC174+AD174+AE174+AF174 -> 1 | AR174: =$C$1+SUMPRODUCT($K$1:$AQ$1,K174:AQ174) -> 86343.318 | AS174: =$C$2+SUMPRODUCT($K$2:$AQ$2,K174:AQ174) -> 110337.43 | AT174: =$C$3+SUMPRODUCT($K$3:$AQ$3,K174:AQ174) -> 11.598879 | AU174: =$C$4+SUMPRODUCT($K$4:$AQ$4,K174:AQ174) -> 111298.1 | AV174: =$C$5+SUMPRODUCT($K$5:$AQ$5,K174:AQ174) -> 11.612801 | AW174: =$C$6+SUMPRODUCT($K$6:$AQ$6,K174:AQ174) -> 111987.02 | AX174: =$C$7+SUMPRODUCT($K$7:$AQ$7,K174:AQ174) -> 11.618823 | AY174: =$C$8+SUMPRODUCT($K$8:$AQ$8,K174:AQ174) -> 11.678126 | AZ174: =$C$9+SUMPRODUCT($K$9:$AQ$9,K174:AQ174) -> 11.645205
B175: =B174 -> NY | C175: 44583 | D175: 4358.4581 | E175: 888.55 | F175: 460.615 | G175: 310.30932 | H175: 113377.68 | I175: =SUM(D175:G175) -> 6017.9324 | J175: =YEAR(C175) -> 2022 | K175: =IF(B175=B174,K174+1,1) -> 4 | L175: =K175^2 -> 16 | M175: =LN(L175) -> 2.7725887 | N175: =IF(K175<127,1,0) -> 1 | O175: =MONTH(C175) -> 1 | P175: =IF($O175=P$13,1,0) -> 1 | Q175: =IF($O175=Q$13,1,0) -> 0 | R175: =IF($O175=R$13,1,0) -> 0 | S175: =IF($O175=S$13,1,0) -> 0 | T175: =IF($O175=T$13,1,0) -> 0 | U175: =IF($O175=U$13,1,0) -> 0 | V175: =IF($O175=V$13,1,0) -> 0 | W175: =IF($O175=W$13,1,0) -> 0 | ... AA175: =IF($O175=AA$13,1,0) -> 0 | AB175: =IF($B175=AB$13,1,0) -> 0 | AC175: =IF($B175=AC$13,1,0) -> 0 | AD175: =IF($B175=AD$13,1,0) -> 0 | AE175: =IF($B175=AE$13,1,0) -> 1 | AF175: =IF($B175=AF$13,1,0) -> 0 | AG175: 4358.4581 | AH175: 888.55 | AI175: 460.615 | AJ175: 310.30932 | AK175: =LN(H175) -> 11.63848 | AL175: =LN(D175+'Models training data'!$Y$4) -> 8.4445504 | AM175: =LN(E175+'Models training data'!$Y$5) -> 6.8602045 | AN175: =LN(F175+'Models training data'!$Y$6) -> 6.2265238 | AO175: =LN(G175+'Models training data'!$Y$7) -> 5.8858616 | AP175: =V175+W175+X175+Y175+Z175 -> 0 | AQ175: =AA175+AC175+AD175+AE175+AF175 -> 1 | AR175: =$C$1+SUMPRODUCT($K$1:$AQ$1,K175:AQ175) -> 86318.928 | AS175: =$C$2+SUMPRODUCT($K$2:$AQ$2,K175:AQ175) -> 110313.34 | AT175: =$C$3+SUMPRODUCT($K$3:$AQ$3,K175:AQ175) -> 11.598622 | AU175: =$C$4+SUMPRODUCT($K$4:$AQ$4,K175:AQ175) -> 111203.34 | AV175: =$C$5+SUMPRODUCT($K$5:$AQ$5,K175:AQ175) -> 11.611525 | AW175: =$C$6+SUMPRODUCT($K$6:$AQ$6,K175:AQ175) -> 111570.77 | AX175: =$C$7+SUMPRODUCT($K$7:$AQ$7,K175:AQ175) -> 11.614032 | AY175: =$C$8+SUMPRODUCT($K$8:$AQ$8,K175:AQ175) -> 11.685864 | AZ175: =$C$9+SUMPRODUCT($K$9:$AQ$9,K175:AQ175) -> 11.647717
B176: =B175 -> NY | C176: 44590 | D176: 4527.7608 | E176: 930.4775 | F176: 483.64375 | G176: 330.64792 | H176: 114366.87 | I176: =SUM(D176:G176) -> 6272.53 | J176: =YEAR(C176) -> 2022 | K176: =IF(B176=B175,K175+1,1) -> 5 | L176: =K176^2 -> 25 | M176: =LN(L176) -> 3.2188758 | N176: =IF(K176<127,1,0) -> 1 | O176: =MONTH(C176) -> 1 | P176: =IF($O176=P$13,1,0) -> 1 | Q176: =IF($O176=Q$13,1,0) -> 0 | R176: =IF($O176=R$13,1,0) -> 0 | S176: =IF($O176=S$13,1,0) -> 0 | T176: =IF($O176=T$13,1,0) -> 0 | U176: =IF($O176=U$13,1,0) -> 0 | V176: =IF($O176=V$13,1,0) -> 0 | W176: =IF($O176=W$13,1,0) -> 0 | ... AA176: =IF($O176=AA$13,1,0) -> 0 | AB176: =IF($B176=AB$13,1,0) -> 0 | AC176: =IF($B176=AC$13,1,0) -> 0 | AD176: =IF($B176=AD$13,1,0) -> 0 | AE176: =IF($B176=AE$13,1,0) -> 1 | AF176: =IF($B176=AF$13,1,0) -> 0 | AG176: 4527.7608 | AH176: 930.4775 | AI176: 483.64375 | AJ176: 330.64792 | AK176: =LN(H176) -> 11.647167 | AL176: =LN(D176+'Models training data'!$Y$4) -> 8.480315 | AM176: =LN(E176+'Models training data'!$Y$5) -> 6.9032347 | AN176: =LN(F176+'Models training data'!$Y$6) -> 6.2710305 | AO176: =LN(G176+'Models training data'!$Y$7) -> 5.9408325 | AP176: =V176+W176+X176+Y176+Z176 -> 0 | AQ176: =AA176+AC176+AD176+AE176+AF176 -> 1 | AR176: =$C$1+SUMPRODUCT($K$1:$AQ$1,K176:AQ176) -> 86294.538 | AS176: =$C$2+SUMPRODUCT($K$2:$AQ$2,K176:AQ176) -> 110289.24 | AT176: =$C$3+SUMPRODUCT($K$3:$AQ$3,K176:AQ176) -> 11.598364 | AU176: =$C$4+SUMPRODUCT($K$4:$AQ$4,K176:AQ176) -> 111109.77 | AV176: =$C$5+SUMPRODUCT($K$5:$AQ$5,K176:AQ176) -> 11.610267 | AW176: =$C$6+SUMPRODUCT($K$6:$AQ$6,K176:AQ176) -> 111247.9 | AX176: =$C$7+SUMPRODUCT($K$7:$AQ$7,K176:AQ176) -> 11.610315 | AY176: =$C$8+SUMPRODUCT($K$8:$AQ$8,K176:AQ176) -> 11.699739 | AZ176: =$C$9+SUMPRODUCT($K$9:$AQ$9,K176:AQ176) -> 11.660825
B177: =B176 -> NY | C177: 44597 | D177: 3944.7736 | E177: 720.49506 | F177: 278.09506 | G177: 168.48767 | H177: 105053.67 | I177: =SUM(D177:G177) -> 5111.8514 | J177: =YEAR(C177) -> 2022 | K177: =IF(B177=B176,K176+1,1) -> 6 | L177: =K177^2 -> 36 | M177: =LN(L177) -> 3.5835189 | N177: =IF(K177<127,1,0) -> 1 | O177: =MONTH(C177) -> 2 | P177: =IF($O177=P$13,1,0) -> 0 | Q177: =IF($O177=Q$13,1,0) -> 1 | R177: =IF($O177=R$13,1,0) -> 0 | S177: =IF($O177=S$13,1,0) -> 0 | T177: =IF($O177=T$13,1,0) -> 0 | U177: =IF($O177=U$13,1,0) -> 0 | V177: =IF($O177=V$13,1,0) -> 0 | W177: =IF($O177=W$13,1,0) -> 0 | ... AA177: =IF($O177=AA$13,1,0) -> 0 | AB177: =IF($B177=AB$13,1,0) -> 0 | AC177: =IF($B177=AC$13,1,0) -> 0 | AD177: =IF($B177=AD$13,1,0) -> 0 | AE177: =IF($B177=AE$13,1,0) -> 1 | AF177: =IF($B177=AF$13,1,0) -> 0 | AG177: 3944.7736 | AH177: 720.49506 | AI177: 278.09506 | AJ177: 168.48767 | AK177: =LN(H177) -> 11.562227 | AL177: =LN(D177+'Models training data'!$Y$4) -> 8.3513701 | AM177: =LN(E177+'Models training data'!$Y$5) -> 6.6663296 | AN177: =LN(F177+'Models training data'!$Y$6) -> 5.7791173 | AO177: =LN(G177+'Models training data'!$Y$7) -> 5.3849129 | AP177: =V177+W177+X177+Y177+Z177 -> 0 | AQ177: =AA177+AC177+AD177+AE177+AF177 -> 1 | AR177: =$C$1+SUMPRODUCT($K$1:$AQ$1,K177:AQ177) -> 85220.436 | AS177: =$C$2+SUMPRODUCT($K$2:$AQ$2,K177:AQ177) -> 109213.03 | AT177: =$C$3+SUMPRODUCT($K$3:$AQ$3,K177:AQ177) -> 11.586412 | AU177: =$C$4+SUMPRODUCT($K$4:$AQ$4,K177:AQ177) -> 110085.41 | AV177: =$C$5+SUMPRODUCT($K$5:$AQ$5,K177:AQ177) -> 11.599077 | AW177: =$C$6+SUMPRODUCT($K$6:$AQ$6,K177:AQ177) -> 110541.79 | AX177: =$C$7+SUMPRODUCT($K$7:$AQ$7,K177:AQ177) -> 11.602766 | AY177: =$C$8+SUMPRODUCT($K$8:$AQ$8,K177:AQ177) -> 11.61769 | AZ177: =$C$9+SUMPRODUCT($K$9:$AQ$9,K177:AQ177) -> 11.537516
B178: =B177 -> NY | C178: 44604 | D178: 3575.4496 | E178: 628.26666 | F178: 269.02672 | G178: 164.21279 | H178: 103928.3 | I178: =SUM(D178:G178) -> 4636.9558 | J178: =YEAR(C178) -> 2022 | K178: =IF(B178=B177,K177+1,1) -> 7 | L178: =K178^2 -> 49 | M178: =LN(L178) -> 3.8918203 | N178: =IF(K178<127,1,0) -> 1 | O178: =MONTH(C178) -> 2 | P178: =IF($O178=P$13,1,0) -> 0 | Q178: =IF($O178=Q$13,1,0) -> 1 | R178: =IF($O178=R$13,1,0) -> 0 | S178: =IF($O178=S$13,1,0) -> 0 | T178: =IF($O178=T$13,1,0) -> 0 | U178: =IF($O178=U$13,1,0) -> 0 | V178: =IF($O178=V$13,1,0) -> 0 | W178: =IF($O178=W$13,1,0) -> 0 | ... AA178: =IF($O178=AA$13,1,0) -> 0 | AB178: =IF($B178=AB$13,1,0) -> 0 | AC178: =IF($B178=AC$13,1,0) -> 0 | AD178: =IF($B178=AD$13,1,0) -> 0 | AE178: =IF($B178=AE$13,1,0) -> 1 | AF178: =IF($B178=AF$13,1,0) -> 0 | AG178: 3575.4496 | AH178: 628.26666 | AI178: 269.02672 | AJ178: 164.21279 | AK178: =LN(H178) -> 11.551457 | AL178: =LN(D178+'Models training data'!$Y$4) -> 8.2601454 | AM178: =LN(E178+'Models training data'!$Y$5) -> 6.5414321 | AN178: =LN(F178+'Models training data'!$Y$6) -> 5.7506826 | AO178: =LN(G178+'Models training data'!$Y$7) -> 5.3651169 | AP178: =V178+W178+X178+Y178+Z178 -> 0 | AQ178: =AA178+AC178+AD178+AE178+AF178 -> 1 | AR178: =$C$1+SUMPRODUCT($K$1:$AQ$1,K178:AQ178) -> 85196.046 | AS178: =$C$2+SUMPRODUCT($K$2:$AQ$2,K178:AQ178) -> 109188.93 | AT178: =$C$3+SUMPRODUCT($K$3:$AQ$3,K178:AQ178) -> 11.586155 | AU178: =$C$4+SUMPRODUCT($K$4:$AQ$4,K178:AQ178) -> 109994.19 | AV178: =$C$5+SUMPRODUCT($K$5:$AQ$5,K178:AQ178) -> 11.597852 | AW178: =$C$6+SUMPRODUCT($K$6:$AQ$6,K178:AQ178) -> 110318.75 | AX178: =$C$7+SUMPRODUCT($K$7:$AQ$7,K178:AQ178) -> 11.600198 | AY178: =$C$8+SUMPRODUCT($K$8:$AQ$8,K178:AQ178) -> 11.597061 | AZ178: =$C$9+SUMPRODUCT($K$9:$AQ$9,K178:AQ178) -> 11.526297
B179: =B178 -> NY | C179: 44611 | D179: 3357.6282 | E179: 595.55341 | F179: 280.18075 | G179: 205.93131 | H179: 105163.14 | I179: =SUM(D179:G179) -> 4439.2937 | J179: =YEAR(C179) -> 2022 | K179: =IF(B179=B178,K178+1,1) -> 8 | L179: =K179^2 -> 64 | M179: =LN(L179) -> 4.1588831 | N179: =IF(K179<127,1,0) -> 1 | O179: =MONTH(C179) -> 2 | P179: =IF($O179=P$13,1,0) -> 0 | Q179: =IF($O179=Q$13,1,0) -> 1 | R179: =IF($O179=R$13,1,0) -> 0 | S179: =IF($O179=S$13,1,0) -> 0 | T179: =IF($O179=T$13,1,0) -> 0 | U179: =IF($O179=U$13,1,0) -> 0 | V179: =IF($O179=V$13,1,0) -> 0 | W179: =IF($O179=W$13,1,0) -> 0 | ... AA179: =IF($O179=AA$13,1,0) -> 0 | AB179: =IF($B179=AB$13,1,0) -> 0 | AC179: =IF($B179=AC$13,1,0) -> 0 | AD179: =IF($B179=AD$13,1,0) -> 0 | AE179: =IF($B179=AE$13,1,0) -> 1 | AF179: =IF($B179=AF$13,1,0) -> 0 | AG179: 3357.6282 | AH179: 595.55341 | AI179: 280.18075 | AJ179: 205.93131 | AK179: =LN(H179) -> 11.563268 | AL179: =LN(D179+'Models training data'!$Y$4) -> 8.2021632 | AM179: =LN(E179+'Models training data'!$Y$5) -> 6.4930963 | AN179: =LN(F179+'Models training data'!$Y$6) -> 5.7855444 | AO179: =LN(G179+'Models training data'!$Y$7) -> 5.5433584 | AP179: =V179+W179+X179+Y179+Z179 -> 0 | AQ179: =AA179+AC179+AD179+AE179+AF179 -> 1 | AR179: =$C$1+SUMPRODUCT($K$1:$AQ$1,K179:AQ179) -> 85171.656 | AS179: =$C$2+SUMPRODUCT($K$2:$AQ$2,K179:AQ179) -> 109164.84 | AT179: =$C$3+SUMPRODUCT($K$3:$AQ$3,K179:AQ179) -> 11.585897 | AU179: =$C$4+SUMPRODUCT($K$4:$AQ$4,K179:AQ179) -> 109904.16 | AV179: =$C$5+SUMPRODUCT($K$5:$AQ$5,K179:AQ179) -> 11.596644 | AW179: =$C$6+SUMPRODUCT($K$6:$AQ$6,K179:AQ179) -> 110125.55 | AX179: =$C$7+SUMPRODUCT($K$7:$AQ$7,K179:AQ179) -> 11.597974 | AY179: =$C$8+SUMPRODUCT($K$8:$AQ$8,K179:AQ179) -> 11.596018 | AZ179: =$C$9+SUMPRODUCT($K$9:$AQ$9,K179:AQ179) -> 11.548898
B180: =B179 -> NY | C180: 44618 | D180: 3247.894 | E180: 593.2678 | F180: 293.96005 | G180: 196.9667 | H180: 105167.52 | I180: =SUM(D180:G180) -> 4332.0885 | J180: =YEAR(C180) -> 2022 | K180: =IF(B180=B179,K179+1,1) -> 9 | L180: =K180^2 -> 81 | M180: =LN(L180) -> 4.3944492 | N180: =IF(K180<127,1,0) -> 1 | O180: =MONTH(C180) -> 2 | P180: =IF($O180=P$13,1,0) -> 0 | Q180: =IF($O180=Q$13,1,0) -> 1 | R180: =IF($O180=R$13,1,0) -> 0 | S180: =IF($O180=S$13,1,0) -> 0 | T180: =IF($O180=T$13,1,0) -> 0 | U180: =IF($O180=U$13,1,0) -> 0 | V180: =IF($O180=V$13,1,0) -> 0 | W180: =IF($O180=W$13,1,0) -> 0 | ... AA180: =IF($O180=AA$13,1,0) -> 0 | AB180: =IF($B180=AB$13,1,0) -> 0 | AC180: =IF($B180=AC$13,1,0) -> 0 | AD180: =IF($B180=AD$13,1,0) -> 0 | AE180: =IF($B180=AE$13,1,0) -> 1 | AF180: =IF($B180=AF$13,1,0) -> 0 | AG180: 3247.894 | AH180: 593.2678 | AI180: 293.96005 | AJ180: 196.9667 | AK180: =LN(H180) -> 11.56331 | AL180: =LN(D180+'Models training data'!$Y$4) -> 8.1716279 | AM180: =LN(E180+'Models training data'!$Y$5) -> 6.4896302 | AN180: =LN(F180+'Models training data'!$Y$6) -> 5.8269982 | AO180: =LN(G180+'Models training data'!$Y$7) -> 5.5076465 | AP180: =V180+W180+X180+Y180+Z180 -> 0 | AQ180: =AA180+AC180+AD180+AE180+AF180 -> 1 | AR180: =$C$1+SUMPRODUCT($K$1:$AQ$1,K180:AQ180) -> 85147.265 | AS180: =$C$2+SUMPRODUCT($K$2:$AQ$2,K180:AQ180) -> 109140.74 | AT180: =$C$3+SUMPRODUCT($K$3:$AQ$3,K180:AQ180) -> 11.585639 | AU180: =$C$4+SUMPRODUCT($K$4:$AQ$4,K180:AQ180) -> 109815.3 | AV180: =$C$5+SUMPRODUCT($K$5:$AQ$5,K180:AQ180) -> 11.595453 | AW180: =$C$6+SUMPRODUCT($K$6:$AQ$6,K180:AQ180) -> 109955.12 | AX180: =$C$7+SUMPRODUCT($K$7:$AQ$7,K180:AQ180) -> 11.596013 | AY180: =$C$8+SUMPRODUCT($K$8:$AQ$8,K180:AQ180) -> 11.593119 | AZ180: =$C$9+SUMPRODUCT($K$9:$AQ$9,K180:AQ180) -> 11.547735
B181: =B180 -> NY | C181: 44625 | D181: 3215.9577 | E181: 606.89954 | F181: 308.63508 | G181: 186.84934 | H181: 105289.32 | I181: =SUM(D181:G181) -> 4318.3416 | J181: =YEAR(C181) -> 2022 | K181: =IF(B181=B180,K180+1,1) -> 10 | L181: =K181^2 -> 100 | M181: =LN(L181) -> 4.6051702 | N181: =IF(K181<127,1,0) -> 1 | O181: =MONTH(C181) -> 3 | P181: =IF($O181=P$13,1,0) -> 0 | Q181: =IF($O181=Q$13,1,0) -> 0 | R181: =IF($O181=R$13,1,0) -> 1 | S181: =IF($O181=S$13,1,0) -> 0 | T181: =IF($O181=T$13,1,0) -> 0 | U181: =IF($O181=U$13,1,0) -> 0 | V181: =IF($O181=V$13,1,0) -> 0 | W181: =IF($O181=W$13,1,0) -> 0 | ... AA181: =IF($O181=AA$13,1,0) -> 0 | AB181: =IF($B181=AB$13,1,0) -> 0 | AC181: =IF($B181=AC$13,1,0) -> 0 | AD181: =IF($B181=AD$13,1,0) -> 0 | AE181: =IF($B181=AE$13,1,0) -> 1 | AF181: =IF($B181=AF$13,1,0) -> 0 | AG181: 3215.9577 | AH181: 606.89954 | AI181: 308.63508 | AJ181: 186.84934 | AK181: =LN(H181) -> 11.564467 | AL181: =LN(D181+'Models training data'!$Y$4) -> 8.1625631 | AM181: =LN(E181+'Models training data'!$Y$5) -> 6.5101268 | AN181: =LN(F181+'Models training data'!$Y$6) -> 5.8693352 | AO181: =LN(G181+'Models training data'!$Y$7) -> 5.4657485 | AP181: =V181+W181+X181+Y181+Z181 -> 0 | AQ181: =AA181+AC181+AD181+AE181+AF181 -> 1 | AR181: =$C$1+SUMPRODUCT($K$1:$AQ$1,K181:AQ181) -> 84207.664 | AS181: =$C$2+SUMPRODUCT($K$2:$AQ$2,K181:AQ181) -> 108199.03 | AT181: =$C$3+SUMPRODUCT($K$3:$AQ$3,K181:AQ181) -> 11.574575 | AU181: =$C$4+SUMPRODUCT($K$4:$AQ$4,K181:AQ181) -> 108766.01 | AV181: =$C$5+SUMPRODUCT($K$5:$AQ$5,K181:AQ181) -> 11.582858 | AW181: =$C$6+SUMPRODUCT($K$6:$AQ$6,K181:AQ181) -> 109055.71 | AX181: =$C$7+SUMPRODUCT($K$7:$AQ$7,K181:AQ181) -> 11.585577 | AY181: =$C$8+SUMPRODUCT($K$8:$AQ$8,K181:AQ181) -> 11.5937 | AZ181: =$C$9+SUMPRODUCT($K$9:$AQ$9,K181:AQ181) -> 11.547158
B182: =B181 -> NY | C182: 44632 | D182: 3240.7238 | E182: 629.2287 | F182: 324.06454 | G182: 226.82025 | H182: 106913.68 | I182: =SUM(D182:G182) -> 4420.8373 | J182: =YEAR(C182) -> 2022 | K182: =IF(B182=B181,K181+1,1) -> 11 | L182: =K182^2 -> 121 | M182: =LN(L182) -> 4.7957905 | N182: =IF(K182<127,1,0) -> 1 | O182: =MONTH(C182) -> 3 | P182: =IF($O182=P$13,1,0) -> 0 | Q182: =IF($O182=Q$13,1,0) -> 0 | R182: =IF($O182=R$13,1,0) -> 1 | S182: =IF($O182=S$13,1,0) -> 0 | T182: =IF($O182=T$13,1,0) -> 0 | U182: =IF($O182=U$13,1,0) -> 0 | V182: =IF($O182=V$13,1,0) -> 0 | W182: =IF($O182=W$13,1,0) -> 0 | ... AA182: =IF($O182=AA$13,1,0) -> 0 | AB182: =IF($B182=AB$13,1,0) -> 0 | AC182: =IF($B182=AC$13,1,0) -> 0 | AD182: =IF($B182=AD$13,1,0) -> 0 | AE182: =IF($B182=AE$13,1,0) -> 1 | AF182: =IF($B182=AF$13,1,0) -> 0 | AG182: 3240.7238 | AH182: 629.2287 | AI182: 324.06454 | AJ182: 226.82025 | AK182: =LN(H182) -> 11.579777 | AL182: =LN(D182+'Models training data'!$Y$4) -> 8.1695999 | AM182: =LN(E182+'Models training data'!$Y$5) -> 6.5428188 | AN182: =LN(F182+'Models training data'!$Y$6) -> 5.9119965 | AO182: =LN(G182+'Models training data'!$Y$7) -> 5.6219348 | AP182: =V182+W182+X182+Y182+Z182 -> 0 | AQ182: =AA182+AC182+AD182+AE182+AF182 -> 1 | AR182: =$C$1+SUMPRODUCT($K$1:$AQ$1,K182:AQ182) -> 84183.274 | AS182: =$C$2+SUMPRODUCT($K$2:$AQ$2,K182:AQ182) -> 108174.93 | AT182: =$C$3+SUMPRODUCT($K$3:$AQ$3,K182:AQ182) -> 11.574317 | AU182: =$C$4+SUMPRODUCT($K$4:$AQ$4,K182:AQ182) -> 108679.51 | AV182: =$C$5+SUMPRODUCT($K$5:$AQ$5,K182:AQ182) -> 11.581701 | AW182: =$C$6+SUMPRODUCT($K$6:$AQ$6,K182:AQ182) -> 108917.81 | AX182: =$C$7+SUMPRODUCT($K$7:$AQ$7,K182:AQ182) -> 11.583989 | AY182: =$C$8+SUMPRODUCT($K$8:$AQ$8,K182:AQ182) -> 11.604595 | AZ182: =$C$9+SUMPRODUCT($K$9:$AQ$9,K182:AQ182) -> 11.571938
B183: =B182 -> NY | C183: 44639 | D183: 3307.5379 | E183: 656.68222 | F183: 340.26754 | G183: 242.17362 | H183: 107860.35 | I183: =SUM(D183:G183) -> 4546.6612 | J183: =YEAR(C183) -> 2022 | K183: =IF(B183=B182,K182+1,1) -> 12 | L183: =K183^2 -> 144 | M183: =LN(L183) -> 4.9698133 | N183: =IF(K183<127,1,0) -> 1 | O183: =MONTH(C183) -> 3 | P183: =IF($O183=P$13,1,0) -> 0 | Q183: =IF($O183=Q$13,1,0) -> 0 | R183: =IF($O183=R$13,1,0) -> 1 | S183: =IF($O183=S$13,1,0) -> 0 | T183: =IF($O183=T$13,1,0) -> 0 | U183: =IF($O183=U$13,1,0) -> 0 | V183: =IF($O183=V$13,1,0) -> 0 | W183: =IF($O183=W$13,1,0) -> 0 | ... AA183: =IF($O183=AA$13,1,0) -> 0 | AB183: =IF($B183=AB$13,1,0) -> 0 | AC183: =IF($B183=AC$13,1,0) -> 0 | AD183: =IF($B183=AD$13,1,0) -> 0 | AE183: =IF($B183=AE$13,1,0) -> 1 | AF183: =IF($B183=AF$13,1,0) -> 0 | AG183: 3307.5379 | AH183: 656.68222 | AI183: 340.26754 | AJ183: 242.17362 | AK183: =LN(H183) -> 11.588593 | AL183: =LN(D183+'Models training data'!$Y$4) -> 8.1883403 | AM183: =LN(E183+'Models training data'!$Y$5) -> 6.5816016 | AN183: =LN(F183+'Models training data'!$Y$6) -> 5.9549199 | AO183: =LN(G183+'Models training data'!$Y$7) -> 5.67599 | AP183: =V183+W183+X183+Y183+Z183 -> 0 | AQ183: =AA183+AC183+AD183+AE183+AF183 -> 1 | AR183: =$C$1+SUMPRODUCT($K$1:$AQ$1,K183:AQ183) -> 84158.884 | AS183: =$C$2+SUMPRODUCT($K$2:$AQ$2,K183:AQ183) -> 108150.84 | AT183: =$C$3+SUMPRODUCT($K$3:$AQ$3,K183:AQ183) -> 11.574059 | AU183: =$C$4+SUMPRODUCT($K$4:$AQ$4,K183:AQ183) -> 108594.19 | AV183: =$C$5+SUMPRODUCT($K$5:$AQ$5,K183:AQ183) -> 11.580561 | AW183: =$C$6+SUMPRODUCT($K$6:$AQ$6,K183:AQ183) -> 108791.91 | AX183: =$C$7+SUMPRODUCT($K$7:$AQ$7,K183:AQ183) -> 11.58254 | AY183: =$C$8+SUMPRODUCT($K$8:$AQ$8,K183:AQ183) -> 11.613144 | AZ183: =$C$9+SUMPRODUCT($K$9:$AQ$9,K183:AQ183) -> 11.584433
B184: =B183 -> NY | C184: 44646 | D184: 3406.2592 | E184: 687.51237 | F184: 357.28089 | G184: 241.59452 | H184: 108452.52 | I184: =SUM(D184:G184) -> 4692.647 | J184: =YEAR(C184) -> 2022 | K184: =IF(B184=B183,K183+1,1) -> 13 | L184: =K184^2 -> 169 | M184: =LN(L184) -> 5.1298987 | N184: =IF(K184<127,1,0) -> 1 | O184: =MONTH(C184) -> 3 | P184: =IF($O184=P$13,1,0) -> 0 | Q184: =IF($O184=Q$13,1,0) -> 0 | R184: =IF($O184=R$13,1,0) -> 1 | S184: =IF($O184=S$13,1,0) -> 0 | T184: =IF($O184=T$13,1,0) -> 0 | U184: =IF($O184=U$13,1,0) -> 0 | V184: =IF($O184=V$13,1,0) -> 0 | W184: =IF($O184=W$13,1,0) -> 0 | ... AA184: =IF($O184=AA$13,1,0) -> 0 | AB184: =IF($B184=AB$13,1,0) -> 0 | AC184: =IF($B184=AC$13,1,0) -> 0 | AD184: =IF($B184=AD$13,1,0) -> 0 | AE184: =IF($B184=AE$13,1,0) -> 1 | AF184: =IF($B184=AF$13,1,0) -> 0 | AG184: 3406.2592 | AH184: 687.51237 | AI184: 357.28089 | AJ184: 241.59452 | AK184: =LN(H184) -> 11.594068 | AL184: =LN(D184+'Models training data'!$Y$4) -> 8.215403 | AM184: =LN(E184+'Models training data'!$Y$5) -> 6.6234335 | AN184: =LN(F184+'Models training data'!$Y$6) -> 5.998091 | AO184: =LN(G184+'Models training data'!$Y$7) -> 5.6740033 | AP184: =V184+W184+X184+Y184+Z184 -> 0 | AQ184: =AA184+AC184+AD184+AE184+AF184 -> 1 | AR184: =$C$1+SUMPRODUCT($K$1:$AQ$1,K184:AQ184) -> 84134.493 | AS184: =$C$2+SUMPRODUCT($K$2:$AQ$2,K184:AQ184) -> 108126.74 | AT184: =$C$3+SUMPRODUCT($K$3:$AQ$3,K184:AQ184) -> 11.573802 | AU184: =$C$4+SUMPRODUCT($K$4:$AQ$4,K184:AQ184) -> 108510.04 | AV184: =$C$5+SUMPRODUCT($K$5:$AQ$5,K184:AQ184) -> 11.579438 | AW184: =$C$6+SUMPRODUCT($K$6:$AQ$6,K184:AQ184) -> 108676.1 | AX184: =$C$7+SUMPRODUCT($K$7:$AQ$7,K184:AQ184) -> 11.581207 | AY184: =$C$8+SUMPRODUCT($K$8:$AQ$8,K184:AQ184) -> 11.620308 | AZ184: =$C$9+SUMPRODUCT($K$9:$AQ$9,K184:AQ184) -> 11.590203
... B328: =B327 -> NY | C328: 45654 | D328: 3770.4463 | E328: 754.55793 | F328: 380.59572 | G328: 273.09806 | H328: 113175.25 | I328: =SUM(D328:G328) -> 5178.698 | J328: =YEAR(C328) -> 2024 | K328: =IF(B328=B327,K327+1,1) -> 157 | L328: =K328^2 -> 24649 | M328: =LN(L328) -> 10.112492 | N328: =IF(K328<127,1,0) -> 0 | O328: =MONTH(C328) -> 12 | P328: =IF($O328=P$13,1,0) -> 0 | Q328: =IF($O328=Q$13,1,0) -> 0 | R328: =IF($O328=R$13,1,0) -> 0 | S328: =IF($O328=S$13,1,0) -> 0 | T328: =IF($O328=T$13,1,0) -> 0 | U328: =IF($O328=U$13,1,0) -> 0 | V328: =IF($O328=V$13,1,0) -> 0 | W328: =IF($O328=W$13,1,0) -> 0 | ... AA328: =IF($O328=AA$13,1,0) -> 1 | AB328: =IF($B328=AB$13,1,0) -> 0 | AC328: =IF($B328=AC$13,1,0) -> 0 | AD328: =IF($B328=AD$13,1,0) -> 0 | AE328: =IF($B328=AE$13,1,0) -> 1 | AF328: =IF($B328=AF$13,1,0) -> 0 | AG328: 3770.4463 | AH328: 754.55793 | AI328: 380.59572 | AJ328: 273.09806 | AK328: =LN(H328) -> 11.636693 | AL328: =LN(D328+'Models training data'!$Y$4) -> 8.3093453 | AM328: =LN(E328+'Models training data'!$Y$5) -> 6.7087798 | AN328: =LN(F328+'Models training data'!$Y$6) -> 6.0543788 | AO328: =LN(G328+'Models training data'!$Y$7) -> 5.7767277 | AP328: =V328+W328+X328+Y328+Z328 -> 0 | AQ328: =AA328+AC328+AD328+AE328+AF328 -> 2 | AR328: =$C$1+SUMPRODUCT($K$1:$AQ$1,K328:AQ328) -> 81456.478 | AS328: =$C$2+SUMPRODUCT($K$2:$AQ$2,K328:AQ328) -> 105488.18 | AT328: =$C$3+SUMPRODUCT($K$3:$AQ$3,K328:AQ328) -> 11.545131 | AU328: =$C$4+SUMPRODUCT($K$4:$AQ$4,K328:AQ328) -> 110138.8 | AV328: =$C$5+SUMPRODUCT($K$5:$AQ$5,K328:AQ328) -> 11.611805 | AW328: =$C$6+SUMPRODUCT($K$6:$AQ$6,K328:AQ328) -> 106297.21 | AX328: =$C$7+SUMPRODUCT($K$7:$AQ$7,K328:AQ328) -> 11.552862 | AY328: =$C$8+SUMPRODUCT($K$8:$AQ$8,K328:AQ328) -> 11.545182 | AZ328: =$C$9+SUMPRODUCT($K$9:$AQ$9,K328:AQ328) -> 11.618082
...

Sheet EDA
A1: SPEND | AJ1: 2024 SPEND | AR1: SALES
AL26: 2024 Spend
AL27: Facebook_spend | AM27: =GETPIVOTDATA("Sum of Facebook_spend_",$AL$59) -> 40517.032
AL28: CT | AM28: 4802.1835
AL29: DL | AM29: 3979.9587
AL30: MD | AM30: 3998.8607
K31: WEEKLY AND MONTHLY SPENDING BY STATE | T31: SPEND TREND | W31: TRENDS | AL31: NJ | AM31: 5662.4037
K32: Year | L32: Months (Date) | M32: Date | N32: Sum of Facebook_spend_ | O32: Sum of YouTube_spend | P32: Sum of Radio_Spend | Q32: Sum of TV_Spend | R32: Sum of Total Spend | T32: Row Labels | U32: Sum of Total Spend | W32: Row Labels | X32: Sum of Facebook_spend_ | Y32: Sum of YouTube_spend | Z32: Sum of Radio_Spend | AA32: Sum of TV_Spend | AL32: NY | AM32: 11979.424
A33: SPEND BY STATE | D33: SALE BY STATE | G33: SPEND BY TACTIC | K33: 2022 | L33: Jan | M33: 44562 | N33: 691.11267 | O33: 1040 | P33: 2080 | Q33: 10530 | R33: 14341.113 | T33: 44562 | U33: 14341.113 | W33: 2022 | X33: 87576.028 | Y33: 61941.871 | Z33: 123026.79 | AA33: 463736.31 | AL33: PA | AM33: 10094.201
